2022-03-01 19:30:26.817263:新列表已生成！共有22张卡片
2022-03-01 19:58:42.000470:新列表已生成！共有0张卡片
Traceback (most recent call last):
  File "/usr/lib/python3.6/wsgiref/handlers.py", line 138, in run
    self.finish_response()
  File "/usr/lib/python3.6/wsgiref/handlers.py", line 180, in finish_response
    self.write(data)
  File "/usr/lib/python3.6/wsgiref/handlers.py", line 274, in write
    self.send_headers()
  File "/usr/lib/python3.6/wsgiref/handlers.py", line 332, in send_headers
    self.send_preamble()
  File "/usr/lib/python3.6/wsgiref/handlers.py", line 252, in send_preamble
    self._write(('HTTP/%s %s\r\n' % (self.http_version,self.status)).encode('iso-8859-1'))
  File "/usr/lib/python3.6/wsgiref/handlers.py", line 453, in _write
    result = self.stdout.write(data)
  File "/usr/lib/python3.6/socketserver.py", line 803, in write
    self._sock.sendall(b)
ConnectionResetError: [Errno 104] Connection reset by peer
----------------------------------------
Exception happened during processing of request from ('66.23.238.6', 50830)
Traceback (most recent call last):
  File "/usr/lib/python3.6/wsgiref/handlers.py", line 138, in run
    self.finish_response()
  File "/usr/lib/python3.6/wsgiref/handlers.py", line 180, in finish_response
    self.write(data)
  File "/usr/lib/python3.6/wsgiref/handlers.py", line 274, in write
    self.send_headers()
  File "/usr/lib/python3.6/wsgiref/handlers.py", line 332, in send_headers
    self.send_preamble()
  File "/usr/lib/python3.6/wsgiref/handlers.py", line 252, in send_preamble
    self._write(('HTTP/%s %s\r\n' % (self.http_version,self.status)).encode('iso-8859-1'))
  File "/usr/lib/python3.6/wsgiref/handlers.py", line 453, in _write
    result = self.stdout.write(data)
  File "/usr/lib/python3.6/socketserver.py", line 803, in write
    self._sock.sendall(b)
ConnectionResetError: [Errno 104] Connection reset by peer

During handling of the above exception, another exception occurred:

Traceback (most recent call last):
  File "/usr/lib/python3.6/wsgiref/handlers.py", line 141, in run
    self.handle_error()
  File "/usr/local/lib/python3.6/dist-packages/django/core/servers/basehttp.py", line 119, in handle_error
    super().handle_error()
  File "/usr/lib/python3.6/wsgiref/handlers.py", line 368, in handle_error
    self.finish_response()
  File "/usr/lib/python3.6/wsgiref/handlers.py", line 180, in finish_response
    self.write(data)
  File "/usr/lib/python3.6/wsgiref/handlers.py", line 274, in write
    self.send_headers()
  File "/usr/lib/python3.6/wsgiref/handlers.py", line 331, in send_headers
    if not self.origin_server or self.client_is_modern():
  File "/usr/lib/python3.6/wsgiref/handlers.py", line 344, in client_is_modern
    return self.environ['SERVER_PROTOCOL'].upper() != 'HTTP/0.9'
TypeError: 'NoneType' object is not subscriptable

During handling of the above exception, another exception occurred:

Traceback (most recent call last):
  File "/usr/lib/python3.6/socketserver.py", line 654, in process_request_thread
    self.finish_request(request, client_address)
  File "/usr/lib/python3.6/socketserver.py", line 364, in finish_request
    self.RequestHandlerClass(request, client_address, self)
  File "/usr/lib/python3.6/socketserver.py", line 724, in __init__
    self.handle()
  File "/usr/local/lib/python3.6/dist-packages/django/core/servers/basehttp.py", line 172, in handle
    self.handle_one_request()
  File "/usr/local/lib/python3.6/dist-packages/django/core/servers/basehttp.py", line 197, in handle_one_request
    handler.run(self.server.get_app())
  File "/usr/lib/python3.6/wsgiref/handlers.py", line 144, in run
    self.close()
  File "/usr/local/lib/python3.6/dist-packages/django/core/servers/basehttp.py", line 114, in close
    super().close()
  File "/usr/lib/python3.6/wsgiref/simple_server.py", line 35, in close
    self.status.split(' ',1)[0], self.bytes_sent
AttributeError: 'NoneType' object has no attribute 'split'
----------------------------------------
Traceback (most recent call last):
  File "/usr/lib/python3.6/wsgiref/handlers.py", line 138, in run
    self.finish_response()
  File "/usr/lib/python3.6/wsgiref/handlers.py", line 180, in finish_response
    self.write(data)
  File "/usr/lib/python3.6/wsgiref/handlers.py", line 274, in write
    self.send_headers()
  File "/usr/lib/python3.6/wsgiref/handlers.py", line 332, in send_headers
    self.send_preamble()
  File "/usr/lib/python3.6/wsgiref/handlers.py", line 252, in send_preamble
    self._write(('HTTP/%s %s\r\n' % (self.http_version,self.status)).encode('iso-8859-1'))
  File "/usr/lib/python3.6/wsgiref/handlers.py", line 453, in _write
    result = self.stdout.write(data)
  File "/usr/lib/python3.6/socketserver.py", line 803, in write
    self._sock.sendall(b)
ConnectionResetError: [Errno 104] Connection reset by peer
----------------------------------------
Exception happened during processing of request from ('92.118.234.202', 49426)
Traceback (most recent call last):
  File "/usr/lib/python3.6/wsgiref/handlers.py", line 138, in run
    self.finish_response()
  File "/usr/lib/python3.6/wsgiref/handlers.py", line 180, in finish_response
    self.write(data)
  File "/usr/lib/python3.6/wsgiref/handlers.py", line 274, in write
    self.send_headers()
  File "/usr/lib/python3.6/wsgiref/handlers.py", line 332, in send_headers
    self.send_preamble()
  File "/usr/lib/python3.6/wsgiref/handlers.py", line 252, in send_preamble
    self._write(('HTTP/%s %s\r\n' % (self.http_version,self.status)).encode('iso-8859-1'))
  File "/usr/lib/python3.6/wsgiref/handlers.py", line 453, in _write
    result = self.stdout.write(data)
  File "/usr/lib/python3.6/socketserver.py", line 803, in write
    self._sock.sendall(b)
ConnectionResetError: [Errno 104] Connection reset by peer

During handling of the above exception, another exception occurred:

Traceback (most recent call last):
  File "/usr/lib/python3.6/wsgiref/handlers.py", line 141, in run
    self.handle_error()
  File "/usr/local/lib/python3.6/dist-packages/django/core/servers/basehttp.py", line 119, in handle_error
    super().handle_error()
  File "/usr/lib/python3.6/wsgiref/handlers.py", line 368, in handle_error
    self.finish_response()
  File "/usr/lib/python3.6/wsgiref/handlers.py", line 180, in finish_response
    self.write(data)
  File "/usr/lib/python3.6/wsgiref/handlers.py", line 274, in write
    self.send_headers()
  File "/usr/lib/python3.6/wsgiref/handlers.py", line 331, in send_headers
    if not self.origin_server or self.client_is_modern():
  File "/usr/lib/python3.6/wsgiref/handlers.py", line 344, in client_is_modern
    return self.environ['SERVER_PROTOCOL'].upper() != 'HTTP/0.9'
TypeError: 'NoneType' object is not subscriptable

During handling of the above exception, another exception occurred:

Traceback (most recent call last):
  File "/usr/lib/python3.6/socketserver.py", line 654, in process_request_thread
    self.finish_request(request, client_address)
  File "/usr/lib/python3.6/socketserver.py", line 364, in finish_request
    self.RequestHandlerClass(request, client_address, self)
  File "/usr/lib/python3.6/socketserver.py", line 724, in __init__
    self.handle()
  File "/usr/local/lib/python3.6/dist-packages/django/core/servers/basehttp.py", line 172, in handle
    self.handle_one_request()
  File "/usr/local/lib/python3.6/dist-packages/django/core/servers/basehttp.py", line 197, in handle_one_request
    handler.run(self.server.get_app())
  File "/usr/lib/python3.6/wsgiref/handlers.py", line 144, in run
    self.close()
  File "/usr/local/lib/python3.6/dist-packages/django/core/servers/basehttp.py", line 114, in close
    super().close()
  File "/usr/lib/python3.6/wsgiref/simple_server.py", line 35, in close
    self.status.split(' ',1)[0], self.bytes_sent
AttributeError: 'NoneType' object has no attribute 'split'
----------------------------------------
Traceback (most recent call last):
  File "/usr/lib/python3.6/wsgiref/handlers.py", line 138, in run
    self.finish_response()
  File "/usr/lib/python3.6/wsgiref/handlers.py", line 180, in finish_response
    self.write(data)
  File "/usr/lib/python3.6/wsgiref/handlers.py", line 274, in write
    self.send_headers()
  File "/usr/lib/python3.6/wsgiref/handlers.py", line 332, in send_headers
    self.send_preamble()
  File "/usr/lib/python3.6/wsgiref/handlers.py", line 252, in send_preamble
    self._write(('HTTP/%s %s\r\n' % (self.http_version,self.status)).encode('iso-8859-1'))
  File "/usr/lib/python3.6/wsgiref/handlers.py", line 453, in _write
    result = self.stdout.write(data)
  File "/usr/lib/python3.6/socketserver.py", line 803, in write
    self._sock.sendall(b)
ConnectionResetError: [Errno 104] Connection reset by peer
----------------------------------------
Exception happened during processing of request from ('66.23.238.6', 55360)
Traceback (most recent call last):
  File "/usr/lib/python3.6/wsgiref/handlers.py", line 138, in run
    self.finish_response()
  File "/usr/lib/python3.6/wsgiref/handlers.py", line 180, in finish_response
    self.write(data)
  File "/usr/lib/python3.6/wsgiref/handlers.py", line 274, in write
    self.send_headers()
  File "/usr/lib/python3.6/wsgiref/handlers.py", line 332, in send_headers
    self.send_preamble()
  File "/usr/lib/python3.6/wsgiref/handlers.py", line 252, in send_preamble
    self._write(('HTTP/%s %s\r\n' % (self.http_version,self.status)).encode('iso-8859-1'))
  File "/usr/lib/python3.6/wsgiref/handlers.py", line 453, in _write
    result = self.stdout.write(data)
  File "/usr/lib/python3.6/socketserver.py", line 803, in write
    self._sock.sendall(b)
ConnectionResetError: [Errno 104] Connection reset by peer

During handling of the above exception, another exception occurred:

Traceback (most recent call last):
  File "/usr/lib/python3.6/wsgiref/handlers.py", line 141, in run
    self.handle_error()
  File "/usr/local/lib/python3.6/dist-packages/django/core/servers/basehttp.py", line 119, in handle_error
    super().handle_error()
  File "/usr/lib/python3.6/wsgiref/handlers.py", line 368, in handle_error
    self.finish_response()
  File "/usr/lib/python3.6/wsgiref/handlers.py", line 180, in finish_response
    self.write(data)
  File "/usr/lib/python3.6/wsgiref/handlers.py", line 274, in write
    self.send_headers()
  File "/usr/lib/python3.6/wsgiref/handlers.py", line 331, in send_headers
    if not self.origin_server or self.client_is_modern():
  File "/usr/lib/python3.6/wsgiref/handlers.py", line 344, in client_is_modern
    return self.environ['SERVER_PROTOCOL'].upper() != 'HTTP/0.9'
TypeError: 'NoneType' object is not subscriptable

During handling of the above exception, another exception occurred:

Traceback (most recent call last):
  File "/usr/lib/python3.6/socketserver.py", line 654, in process_request_thread
    self.finish_request(request, client_address)
  File "/usr/lib/python3.6/socketserver.py", line 364, in finish_request
    self.RequestHandlerClass(request, client_address, self)
  File "/usr/lib/python3.6/socketserver.py", line 724, in __init__
    self.handle()
  File "/usr/local/lib/python3.6/dist-packages/django/core/servers/basehttp.py", line 172, in handle
    self.handle_one_request()
  File "/usr/local/lib/python3.6/dist-packages/django/core/servers/basehttp.py", line 197, in handle_one_request
    handler.run(self.server.get_app())
  File "/usr/lib/python3.6/wsgiref/handlers.py", line 144, in run
    self.close()
  File "/usr/local/lib/python3.6/dist-packages/django/core/servers/basehttp.py", line 114, in close
    super().close()
  File "/usr/lib/python3.6/wsgiref/simple_server.py", line 35, in close
    self.status.split(' ',1)[0], self.bytes_sent
AttributeError: 'NoneType' object has no attribute 'split'
----------------------------------------
Traceback (most recent call last):
  File "/usr/lib/python3.6/wsgiref/handlers.py", line 138, in run
    self.finish_response()
  File "/usr/lib/python3.6/wsgiref/handlers.py", line 180, in finish_response
    self.write(data)
  File "/usr/lib/python3.6/wsgiref/handlers.py", line 274, in write
    self.send_headers()
  File "/usr/lib/python3.6/wsgiref/handlers.py", line 332, in send_headers
    self.send_preamble()
  File "/usr/lib/python3.6/wsgiref/handlers.py", line 252, in send_preamble
    self._write(('HTTP/%s %s\r\n' % (self.http_version,self.status)).encode('iso-8859-1'))
  File "/usr/lib/python3.6/wsgiref/handlers.py", line 453, in _write
    result = self.stdout.write(data)
  File "/usr/lib/python3.6/socketserver.py", line 803, in write
    self._sock.sendall(b)
ConnectionResetError: [Errno 104] Connection reset by peer
----------------------------------------
Exception happened during processing of request from ('104.244.77.146', 46966)
Traceback (most recent call last):
  File "/usr/lib/python3.6/wsgiref/handlers.py", line 138, in run
    self.finish_response()
  File "/usr/lib/python3.6/wsgiref/handlers.py", line 180, in finish_response
    self.write(data)
  File "/usr/lib/python3.6/wsgiref/handlers.py", line 274, in write
    self.send_headers()
  File "/usr/lib/python3.6/wsgiref/handlers.py", line 332, in send_headers
    self.send_preamble()
  File "/usr/lib/python3.6/wsgiref/handlers.py", line 252, in send_preamble
    self._write(('HTTP/%s %s\r\n' % (self.http_version,self.status)).encode('iso-8859-1'))
  File "/usr/lib/python3.6/wsgiref/handlers.py", line 453, in _write
    result = self.stdout.write(data)
  File "/usr/lib/python3.6/socketserver.py", line 803, in write
    self._sock.sendall(b)
ConnectionResetError: [Errno 104] Connection reset by peer

During handling of the above exception, another exception occurred:

Traceback (most recent call last):
  File "/usr/lib/python3.6/wsgiref/handlers.py", line 141, in run
    self.handle_error()
  File "/usr/local/lib/python3.6/dist-packages/django/core/servers/basehttp.py", line 119, in handle_error
    super().handle_error()
  File "/usr/lib/python3.6/wsgiref/handlers.py", line 368, in handle_error
    self.finish_response()
  File "/usr/lib/python3.6/wsgiref/handlers.py", line 180, in finish_response
    self.write(data)
  File "/usr/lib/python3.6/wsgiref/handlers.py", line 274, in write
    self.send_headers()
  File "/usr/lib/python3.6/wsgiref/handlers.py", line 331, in send_headers
    if not self.origin_server or self.client_is_modern():
  File "/usr/lib/python3.6/wsgiref/handlers.py", line 344, in client_is_modern
    return self.environ['SERVER_PROTOCOL'].upper() != 'HTTP/0.9'
TypeError: 'NoneType' object is not subscriptable

During handling of the above exception, another exception occurred:

Traceback (most recent call last):
  File "/usr/lib/python3.6/socketserver.py", line 654, in process_request_thread
    self.finish_request(request, client_address)
  File "/usr/lib/python3.6/socketserver.py", line 364, in finish_request
    self.RequestHandlerClass(request, client_address, self)
  File "/usr/lib/python3.6/socketserver.py", line 724, in __init__
    self.handle()
  File "/usr/local/lib/python3.6/dist-packages/django/core/servers/basehttp.py", line 172, in handle
    self.handle_one_request()
  File "/usr/local/lib/python3.6/dist-packages/django/core/servers/basehttp.py", line 197, in handle_one_request
    handler.run(self.server.get_app())
  File "/usr/lib/python3.6/wsgiref/handlers.py", line 144, in run
    self.close()
  File "/usr/local/lib/python3.6/dist-packages/django/core/servers/basehttp.py", line 114, in close
    super().close()
  File "/usr/lib/python3.6/wsgiref/simple_server.py", line 35, in close
    self.status.split(' ',1)[0], self.bytes_sent
AttributeError: 'NoneType' object has no attribute 'split'
----------------------------------------
Traceback (most recent call last):
  File "/usr/lib/python3.6/wsgiref/handlers.py", line 138, in run
    self.finish_response()
  File "/usr/lib/python3.6/wsgiref/handlers.py", line 180, in finish_response
    self.write(data)
  File "/usr/lib/python3.6/wsgiref/handlers.py", line 274, in write
    self.send_headers()
  File "/usr/lib/python3.6/wsgiref/handlers.py", line 332, in send_headers
    self.send_preamble()
  File "/usr/lib/python3.6/wsgiref/handlers.py", line 252, in send_preamble
    self._write(('HTTP/%s %s\r\n' % (self.http_version,self.status)).encode('iso-8859-1'))
  File "/usr/lib/python3.6/wsgiref/handlers.py", line 453, in _write
    result = self.stdout.write(data)
  File "/usr/lib/python3.6/socketserver.py", line 803, in write
    self._sock.sendall(b)
ConnectionResetError: [Errno 104] Connection reset by peer
----------------------------------------
Exception happened during processing of request from ('92.118.234.202', 34530)
Traceback (most recent call last):
  File "/usr/lib/python3.6/wsgiref/handlers.py", line 138, in run
    self.finish_response()
  File "/usr/lib/python3.6/wsgiref/handlers.py", line 180, in finish_response
    self.write(data)
  File "/usr/lib/python3.6/wsgiref/handlers.py", line 274, in write
    self.send_headers()
  File "/usr/lib/python3.6/wsgiref/handlers.py", line 332, in send_headers
    self.send_preamble()
  File "/usr/lib/python3.6/wsgiref/handlers.py", line 252, in send_preamble
    self._write(('HTTP/%s %s\r\n' % (self.http_version,self.status)).encode('iso-8859-1'))
  File "/usr/lib/python3.6/wsgiref/handlers.py", line 453, in _write
    result = self.stdout.write(data)
  File "/usr/lib/python3.6/socketserver.py", line 803, in write
    self._sock.sendall(b)
ConnectionResetError: [Errno 104] Connection reset by peer

During handling of the above exception, another exception occurred:

Traceback (most recent call last):
  File "/usr/lib/python3.6/wsgiref/handlers.py", line 141, in run
    self.handle_error()
  File "/usr/local/lib/python3.6/dist-packages/django/core/servers/basehttp.py", line 119, in handle_error
    super().handle_error()
  File "/usr/lib/python3.6/wsgiref/handlers.py", line 368, in handle_error
    self.finish_response()
  File "/usr/lib/python3.6/wsgiref/handlers.py", line 180, in finish_response
    self.write(data)
  File "/usr/lib/python3.6/wsgiref/handlers.py", line 274, in write
    self.send_headers()
  File "/usr/lib/python3.6/wsgiref/handlers.py", line 331, in send_headers
    if not self.origin_server or self.client_is_modern():
  File "/usr/lib/python3.6/wsgiref/handlers.py", line 344, in client_is_modern
    return self.environ['SERVER_PROTOCOL'].upper() != 'HTTP/0.9'
TypeError: 'NoneType' object is not subscriptable

During handling of the above exception, another exception occurred:

Traceback (most recent call last):
  File "/usr/lib/python3.6/socketserver.py", line 654, in process_request_thread
    self.finish_request(request, client_address)
  File "/usr/lib/python3.6/socketserver.py", line 364, in finish_request
    self.RequestHandlerClass(request, client_address, self)
  File "/usr/lib/python3.6/socketserver.py", line 724, in __init__
    self.handle()
  File "/usr/local/lib/python3.6/dist-packages/django/core/servers/basehttp.py", line 172, in handle
    self.handle_one_request()
  File "/usr/local/lib/python3.6/dist-packages/django/core/servers/basehttp.py", line 197, in handle_one_request
    handler.run(self.server.get_app())
  File "/usr/lib/python3.6/wsgiref/handlers.py", line 144, in run
    self.close()
  File "/usr/local/lib/python3.6/dist-packages/django/core/servers/basehttp.py", line 114, in close
    super().close()
  File "/usr/lib/python3.6/wsgiref/simple_server.py", line 35, in close
    self.status.split(' ',1)[0], self.bytes_sent
AttributeError: 'NoneType' object has no attribute 'split'
----------------------------------------
Traceback (most recent call last):
  File "/usr/lib/python3.6/wsgiref/handlers.py", line 138, in run
    self.finish_response()
  File "/usr/lib/python3.6/wsgiref/handlers.py", line 180, in finish_response
    self.write(data)
  File "/usr/lib/python3.6/wsgiref/handlers.py", line 274, in write
    self.send_headers()
  File "/usr/lib/python3.6/wsgiref/handlers.py", line 332, in send_headers
    self.send_preamble()
  File "/usr/lib/python3.6/wsgiref/handlers.py", line 252, in send_preamble
    self._write(('HTTP/%s %s\r\n' % (self.http_version,self.status)).encode('iso-8859-1'))
  File "/usr/lib/python3.6/wsgiref/handlers.py", line 453, in _write
    result = self.stdout.write(data)
  File "/usr/lib/python3.6/socketserver.py", line 803, in write
    self._sock.sendall(b)
ConnectionResetError: [Errno 104] Connection reset by peer
Traceback (most recent call last):
  File "/usr/lib/python3.6/wsgiref/handlers.py", line 138, in run
    self.finish_response()
  File "/usr/lib/python3.6/wsgiref/handlers.py", line 180, in finish_response
    self.write(data)
  File "/usr/lib/python3.6/wsgiref/handlers.py", line 274, in write
    self.send_headers()
  File "/usr/lib/python3.6/wsgiref/handlers.py", line 332, in send_headers
    self.send_preamble()
  File "/usr/lib/python3.6/wsgiref/handlers.py", line 252, in send_preamble
    self._write(('HTTP/%s %s\r\n' % (self.http_version,self.status)).encode('iso-8859-1'))
  File "/usr/lib/python3.6/wsgiref/handlers.py", line 453, in _write
    result = self.stdout.write(data)
  File "/usr/lib/python3.6/socketserver.py", line 803, in write
    self._sock.sendall(b)
ConnectionResetError: [Errno 104] Connection reset by peer
----------------------------------------
Exception happened during processing of request from ('92.118.234.202', 56594)
Traceback (most recent call last):
  File "/usr/lib/python3.6/wsgiref/handlers.py", line 138, in run
    self.finish_response()
  File "/usr/lib/python3.6/wsgiref/handlers.py", line 180, in finish_response
    self.write(data)
  File "/usr/lib/python3.6/wsgiref/handlers.py", line 274, in write
    self.send_headers()
  File "/usr/lib/python3.6/wsgiref/handlers.py", line 332, in send_headers
    self.send_preamble()
  File "/usr/lib/python3.6/wsgiref/handlers.py", line 252, in send_preamble
    self._write(('HTTP/%s %s\r\n' % (self.http_version,self.status)).encode('iso-8859-1'))
  File "/usr/lib/python3.6/wsgiref/handlers.py", line 453, in _write
    result = self.stdout.write(data)
  File "/usr/lib/python3.6/socketserver.py", line 803, in write
    self._sock.sendall(b)
ConnectionResetError: [Errno 104] Connection reset by peer

During handling of the above exception, another exception occurred:

Traceback (most recent call last):
  File "/usr/lib/python3.6/wsgiref/handlers.py", line 141, in run
    self.handle_error()
  File "/usr/local/lib/python3.6/dist-packages/django/core/servers/basehttp.py", line 119, in handle_error
    super().handle_error()
  File "/usr/lib/python3.6/wsgiref/handlers.py", line 368, in handle_error
    self.finish_response()
  File "/usr/lib/python3.6/wsgiref/handlers.py", line 180, in finish_response
    self.write(data)
  File "/usr/lib/python3.6/wsgiref/handlers.py", line 274, in write
    self.send_headers()
  File "/usr/lib/python3.6/wsgiref/handlers.py", line 331, in send_headers
    if not self.origin_server or self.client_is_modern():
  File "/usr/lib/python3.6/wsgiref/handlers.py", line 344, in client_is_modern
    return self.environ['SERVER_PROTOCOL'].upper() != 'HTTP/0.9'
TypeError: 'NoneType' object is not subscriptable

During handling of the above exception, another exception occurred:

Traceback (most recent call last):
  File "/usr/lib/python3.6/socketserver.py", line 654, in process_request_thread
    self.finish_request(request, client_address)
  File "/usr/lib/python3.6/socketserver.py", line 364, in finish_request
    self.RequestHandlerClass(request, client_address, self)
  File "/usr/lib/python3.6/socketserver.py", line 724, in __init__
    self.handle()
  File "/usr/local/lib/python3.6/dist-packages/django/core/servers/basehttp.py", line 172, in handle
    self.handle_one_request()
  File "/usr/local/lib/python3.6/dist-packages/django/core/servers/basehttp.py", line 197, in handle_one_request
    handler.run(self.server.get_app())
  File "/usr/lib/python3.6/wsgiref/handlers.py", line 144, in run
    self.close()
  File "/usr/local/lib/python3.6/dist-packages/django/core/servers/basehttp.py", line 114, in close
    super().close()
  File "/usr/lib/python3.6/wsgiref/simple_server.py", line 35, in close
    self.status.split(' ',1)[0], self.bytes_sent
AttributeError: 'NoneType' object has no attribute 'split'
----------------------------------------
Traceback (most recent call last):
  File "/usr/lib/python3.6/wsgiref/handlers.py", line 138, in run
    self.finish_response()
  File "/usr/lib/python3.6/wsgiref/handlers.py", line 180, in finish_response
    self.write(data)
  File "/usr/lib/python3.6/wsgiref/handlers.py", line 274, in write
    self.send_headers()
  File "/usr/lib/python3.6/wsgiref/handlers.py", line 332, in send_headers
    self.send_preamble()
  File "/usr/lib/python3.6/wsgiref/handlers.py", line 252, in send_preamble
    self._write(('HTTP/%s %s\r\n' % (self.http_version,self.status)).encode('iso-8859-1'))
  File "/usr/lib/python3.6/wsgiref/handlers.py", line 453, in _write
    result = self.stdout.write(data)
  File "/usr/lib/python3.6/socketserver.py", line 803, in write
    self._sock.sendall(b)
ConnectionResetError: [Errno 104] Connection reset by peer
----------------------------------------
Exception happened during processing of request from ('66.23.238.6', 54494)
Traceback (most recent call last):
  File "/usr/lib/python3.6/wsgiref/handlers.py", line 138, in run
    self.finish_response()
  File "/usr/lib/python3.6/wsgiref/handlers.py", line 180, in finish_response
    self.write(data)
  File "/usr/lib/python3.6/wsgiref/handlers.py", line 274, in write
    self.send_headers()
  File "/usr/lib/python3.6/wsgiref/handlers.py", line 332, in send_headers
    self.send_preamble()
  File "/usr/lib/python3.6/wsgiref/handlers.py", line 252, in send_preamble
    self._write(('HTTP/%s %s\r\n' % (self.http_version,self.status)).encode('iso-8859-1'))
  File "/usr/lib/python3.6/wsgiref/handlers.py", line 453, in _write
    result = self.stdout.write(data)
  File "/usr/lib/python3.6/socketserver.py", line 803, in write
    self._sock.sendall(b)
ConnectionResetError: [Errno 104] Connection reset by peer

During handling of the above exception, another exception occurred:

Traceback (most recent call last):
  File "/usr/lib/python3.6/wsgiref/handlers.py", line 141, in run
    self.handle_error()
  File "/usr/local/lib/python3.6/dist-packages/django/core/servers/basehttp.py", line 119, in handle_error
    super().handle_error()
  File "/usr/lib/python3.6/wsgiref/handlers.py", line 368, in handle_error
    self.finish_response()
  File "/usr/lib/python3.6/wsgiref/handlers.py", line 180, in finish_response
    self.write(data)
  File "/usr/lib/python3.6/wsgiref/handlers.py", line 274, in write
    self.send_headers()
  File "/usr/lib/python3.6/wsgiref/handlers.py", line 331, in send_headers
    if not self.origin_server or self.client_is_modern():
  File "/usr/lib/python3.6/wsgiref/handlers.py", line 344, in client_is_modern
    return self.environ['SERVER_PROTOCOL'].upper() != 'HTTP/0.9'
TypeError: 'NoneType' object is not subscriptable

During handling of the above exception, another exception occurred:

Traceback (most recent call last):
  File "/usr/lib/python3.6/socketserver.py", line 654, in process_request_thread
    self.finish_request(request, client_address)
  File "/usr/lib/python3.6/socketserver.py", line 364, in finish_request
    self.RequestHandlerClass(request, client_address, self)
  File "/usr/lib/python3.6/socketserver.py", line 724, in __init__
    self.handle()
  File "/usr/local/lib/python3.6/dist-packages/django/core/servers/basehttp.py", line 172, in handle
    self.handle_one_request()
  File "/usr/local/lib/python3.6/dist-packages/django/core/servers/basehttp.py", line 197, in handle_one_request
    handler.run(self.server.get_app())
  File "/usr/lib/python3.6/wsgiref/handlers.py", line 144, in run
    self.close()
  File "/usr/local/lib/python3.6/dist-packages/django/core/servers/basehttp.py", line 114, in close
    super().close()
  File "/usr/lib/python3.6/wsgiref/simple_server.py", line 35, in close
    self.status.split(' ',1)[0], self.bytes_sent
AttributeError: 'NoneType' object has no attribute 'split'
----------------------------------------
Traceback (most recent call last):
  File "/usr/lib/python3.6/wsgiref/handlers.py", line 138, in run
    self.finish_response()
  File "/usr/lib/python3.6/wsgiref/handlers.py", line 180, in finish_response
    self.write(data)
  File "/usr/lib/python3.6/wsgiref/handlers.py", line 274, in write
    self.send_headers()
  File "/usr/lib/python3.6/wsgiref/handlers.py", line 332, in send_headers
    self.send_preamble()
  File "/usr/lib/python3.6/wsgiref/handlers.py", line 252, in send_preamble
    self._write(('HTTP/%s %s\r\n' % (self.http_version,self.status)).encode('iso-8859-1'))
  File "/usr/lib/python3.6/wsgiref/handlers.py", line 453, in _write
    result = self.stdout.write(data)
  File "/usr/lib/python3.6/socketserver.py", line 803, in write
    self._sock.sendall(b)
ConnectionResetError: [Errno 104] Connection reset by peer
----------------------------------------
Exception happened during processing of request from ('92.118.234.202', 50790)
Traceback (most recent call last):
  File "/usr/lib/python3.6/wsgiref/handlers.py", line 138, in run
    self.finish_response()
  File "/usr/lib/python3.6/wsgiref/handlers.py", line 180, in finish_response
    self.write(data)
  File "/usr/lib/python3.6/wsgiref/handlers.py", line 274, in write
    self.send_headers()
  File "/usr/lib/python3.6/wsgiref/handlers.py", line 332, in send_headers
    self.send_preamble()
  File "/usr/lib/python3.6/wsgiref/handlers.py", line 252, in send_preamble
    self._write(('HTTP/%s %s\r\n' % (self.http_version,self.status)).encode('iso-8859-1'))
  File "/usr/lib/python3.6/wsgiref/handlers.py", line 453, in _write
    result = self.stdout.write(data)
  File "/usr/lib/python3.6/socketserver.py", line 803, in write
    self._sock.sendall(b)
ConnectionResetError: [Errno 104] Connection reset by peer

During handling of the above exception, another exception occurred:

Traceback (most recent call last):
  File "/usr/lib/python3.6/wsgiref/handlers.py", line 141, in run
    self.handle_error()
  File "/usr/local/lib/python3.6/dist-packages/django/core/servers/basehttp.py", line 119, in handle_error
    super().handle_error()
  File "/usr/lib/python3.6/wsgiref/handlers.py", line 368, in handle_error
    self.finish_response()
  File "/usr/lib/python3.6/wsgiref/handlers.py", line 180, in finish_response
    self.write(data)
  File "/usr/lib/python3.6/wsgiref/handlers.py", line 274, in write
    self.send_headers()
  File "/usr/lib/python3.6/wsgiref/handlers.py", line 331, in send_headers
    if not self.origin_server or self.client_is_modern():
  File "/usr/lib/python3.6/wsgiref/handlers.py", line 344, in client_is_modern
    return self.environ['SERVER_PROTOCOL'].upper() != 'HTTP/0.9'
TypeError: 'NoneType' object is not subscriptable

During handling of the above exception, another exception occurred:

Traceback (most recent call last):
  File "/usr/lib/python3.6/socketserver.py", line 654, in process_request_thread
    self.finish_request(request, client_address)
  File "/usr/lib/python3.6/socketserver.py", line 364, in finish_request
    self.RequestHandlerClass(request, client_address, self)
  File "/usr/lib/python3.6/socketserver.py", line 724, in __init__
    self.handle()
  File "/usr/local/lib/python3.6/dist-packages/django/core/servers/basehttp.py", line 172, in handle
    self.handle_one_request()
  File "/usr/local/lib/python3.6/dist-packages/django/core/servers/basehttp.py", line 197, in handle_one_request
    handler.run(self.server.get_app())
  File "/usr/lib/python3.6/wsgiref/handlers.py", line 144, in run
    self.close()
  File "/usr/local/lib/python3.6/dist-packages/django/core/servers/basehttp.py", line 114, in close
    super().close()
  File "/usr/lib/python3.6/wsgiref/simple_server.py", line 35, in close
    self.status.split(' ',1)[0], self.bytes_sent
AttributeError: 'NoneType' object has no attribute 'split'
----------------------------------------
Traceback (most recent call last):
  File "/usr/lib/python3.6/wsgiref/handlers.py", line 138, in run
    self.finish_response()
  File "/usr/lib/python3.6/wsgiref/handlers.py", line 180, in finish_response
    self.write(data)
  File "/usr/lib/python3.6/wsgiref/handlers.py", line 274, in write
    self.send_headers()
  File "/usr/lib/python3.6/wsgiref/handlers.py", line 332, in send_headers
    self.send_preamble()
  File "/usr/lib/python3.6/wsgiref/handlers.py", line 252, in send_preamble
    self._write(('HTTP/%s %s\r\n' % (self.http_version,self.status)).encode('iso-8859-1'))
  File "/usr/lib/python3.6/wsgiref/handlers.py", line 453, in _write
    result = self.stdout.write(data)
  File "/usr/lib/python3.6/socketserver.py", line 803, in write
    self._sock.sendall(b)
ConnectionResetError: [Errno 104] Connection reset by peer
----------------------------------------
Exception happened during processing of request from ('66.23.238.6', 38346)
Traceback (most recent call last):
  File "/usr/lib/python3.6/wsgiref/handlers.py", line 138, in run
    self.finish_response()
  File "/usr/lib/python3.6/wsgiref/handlers.py", line 180, in finish_response
    self.write(data)
  File "/usr/lib/python3.6/wsgiref/handlers.py", line 274, in write
    self.send_headers()
  File "/usr/lib/python3.6/wsgiref/handlers.py", line 332, in send_headers
    self.send_preamble()
  File "/usr/lib/python3.6/wsgiref/handlers.py", line 252, in send_preamble
    self._write(('HTTP/%s %s\r\n' % (self.http_version,self.status)).encode('iso-8859-1'))
  File "/usr/lib/python3.6/wsgiref/handlers.py", line 453, in _write
    result = self.stdout.write(data)
  File "/usr/lib/python3.6/socketserver.py", line 803, in write
    self._sock.sendall(b)
ConnectionResetError: [Errno 104] Connection reset by peer

During handling of the above exception, another exception occurred:

Traceback (most recent call last):
  File "/usr/lib/python3.6/wsgiref/handlers.py", line 141, in run
    self.handle_error()
  File "/usr/local/lib/python3.6/dist-packages/django/core/servers/basehttp.py", line 119, in handle_error
    super().handle_error()
  File "/usr/lib/python3.6/wsgiref/handlers.py", line 368, in handle_error
    self.finish_response()
  File "/usr/lib/python3.6/wsgiref/handlers.py", line 180, in finish_response
    self.write(data)
  File "/usr/lib/python3.6/wsgiref/handlers.py", line 274, in write
    self.send_headers()
  File "/usr/lib/python3.6/wsgiref/handlers.py", line 331, in send_headers
    if not self.origin_server or self.client_is_modern():
  File "/usr/lib/python3.6/wsgiref/handlers.py", line 344, in client_is_modern
    return self.environ['SERVER_PROTOCOL'].upper() != 'HTTP/0.9'
TypeError: 'NoneType' object is not subscriptable

During handling of the above exception, another exception occurred:

Traceback (most recent call last):
  File "/usr/lib/python3.6/socketserver.py", line 654, in process_request_thread
    self.finish_request(request, client_address)
  File "/usr/lib/python3.6/socketserver.py", line 364, in finish_request
    self.RequestHandlerClass(request, client_address, self)
  File "/usr/lib/python3.6/socketserver.py", line 724, in __init__
    self.handle()
  File "/usr/local/lib/python3.6/dist-packages/django/core/servers/basehttp.py", line 172, in handle
    self.handle_one_request()
  File "/usr/local/lib/python3.6/dist-packages/django/core/servers/basehttp.py", line 197, in handle_one_request
    handler.run(self.server.get_app())
  File "/usr/lib/python3.6/wsgiref/handlers.py", line 144, in run
    self.close()
  File "/usr/local/lib/python3.6/dist-packages/django/core/servers/basehttp.py", line 114, in close
    super().close()
  File "/usr/lib/python3.6/wsgiref/simple_server.py", line 35, in close
    self.status.split(' ',1)[0], self.bytes_sent
AttributeError: 'NoneType' object has no attribute 'split'
----------------------------------------
Traceback (most recent call last):
  File "/usr/lib/python3.6/wsgiref/handlers.py", line 138, in run
    self.finish_response()
  File "/usr/lib/python3.6/wsgiref/handlers.py", line 180, in finish_response
    self.write(data)
  File "/usr/lib/python3.6/wsgiref/handlers.py", line 274, in write
    self.send_headers()
  File "/usr/lib/python3.6/wsgiref/handlers.py", line 332, in send_headers
    self.send_preamble()
  File "/usr/lib/python3.6/wsgiref/handlers.py", line 252, in send_preamble
    self._write(('HTTP/%s %s\r\n' % (self.http_version,self.status)).encode('iso-8859-1'))
  File "/usr/lib/python3.6/wsgiref/handlers.py", line 453, in _write
    result = self.stdout.write(data)
  File "/usr/lib/python3.6/socketserver.py", line 803, in write
    self._sock.sendall(b)
ConnectionResetError: [Errno 104] Connection reset by peer
----------------------------------------
Exception happened during processing of request from ('66.23.238.6', 43114)
Traceback (most recent call last):
  File "/usr/lib/python3.6/wsgiref/handlers.py", line 138, in run
    self.finish_response()
  File "/usr/lib/python3.6/wsgiref/handlers.py", line 180, in finish_response
    self.write(data)
  File "/usr/lib/python3.6/wsgiref/handlers.py", line 274, in write
    self.send_headers()
  File "/usr/lib/python3.6/wsgiref/handlers.py", line 332, in send_headers
    self.send_preamble()
  File "/usr/lib/python3.6/wsgiref/handlers.py", line 252, in send_preamble
    self._write(('HTTP/%s %s\r\n' % (self.http_version,self.status)).encode('iso-8859-1'))
  File "/usr/lib/python3.6/wsgiref/handlers.py", line 453, in _write
    result = self.stdout.write(data)
  File "/usr/lib/python3.6/socketserver.py", line 803, in write
    self._sock.sendall(b)
ConnectionResetError: [Errno 104] Connection reset by peer

During handling of the above exception, another exception occurred:

Traceback (most recent call last):
  File "/usr/lib/python3.6/wsgiref/handlers.py", line 141, in run
    self.handle_error()
  File "/usr/local/lib/python3.6/dist-packages/django/core/servers/basehttp.py", line 119, in handle_error
    super().handle_error()
  File "/usr/lib/python3.6/wsgiref/handlers.py", line 368, in handle_error
    self.finish_response()
  File "/usr/lib/python3.6/wsgiref/handlers.py", line 180, in finish_response
    self.write(data)
  File "/usr/lib/python3.6/wsgiref/handlers.py", line 274, in write
    self.send_headers()
  File "/usr/lib/python3.6/wsgiref/handlers.py", line 331, in send_headers
    if not self.origin_server or self.client_is_modern():
  File "/usr/lib/python3.6/wsgiref/handlers.py", line 344, in client_is_modern
    return self.environ['SERVER_PROTOCOL'].upper() != 'HTTP/0.9'
TypeError: 'NoneType' object is not subscriptable

During handling of the above exception, another exception occurred:

Traceback (most recent call last):
  File "/usr/lib/python3.6/socketserver.py", line 654, in process_request_thread
    self.finish_request(request, client_address)
  File "/usr/lib/python3.6/socketserver.py", line 364, in finish_request
    self.RequestHandlerClass(request, client_address, self)
  File "/usr/lib/python3.6/socketserver.py", line 724, in __init__
    self.handle()
  File "/usr/local/lib/python3.6/dist-packages/django/core/servers/basehttp.py", line 172, in handle
    self.handle_one_request()
  File "/usr/local/lib/python3.6/dist-packages/django/core/servers/basehttp.py", line 197, in handle_one_request
    handler.run(self.server.get_app())
  File "/usr/lib/python3.6/wsgiref/handlers.py", line 144, in run
    self.close()
  File "/usr/local/lib/python3.6/dist-packages/django/core/servers/basehttp.py", line 114, in close
    super().close()
  File "/usr/lib/python3.6/wsgiref/simple_server.py", line 35, in close
    self.status.split(' ',1)[0], self.bytes_sent
AttributeError: 'NoneType' object has no attribute 'split'
----------------------------------------
----------------------------------------
Exception happened during processing of request from ('106.75.212.164', 55526)
Traceback (most recent call last):
  File "/usr/lib/python3.6/socketserver.py", line 654, in process_request_thread
    self.finish_request(request, client_address)
  File "/usr/lib/python3.6/socketserver.py", line 364, in finish_request
    self.RequestHandlerClass(request, client_address, self)
  File "/usr/lib/python3.6/socketserver.py", line 724, in __init__
    self.handle()
  File "/usr/local/lib/python3.6/dist-packages/django/core/servers/basehttp.py", line 174, in handle
    self.handle_one_request()
  File "/usr/local/lib/python3.6/dist-packages/django/core/servers/basehttp.py", line 182, in handle_one_request
    self.raw_requestline = self.rfile.readline(65537)
  File "/usr/lib/python3.6/socket.py", line 586, in readinto
    return self._sock.recv_into(b)
ConnectionResetError: [Errno 104] Connection reset by peer
----------------------------------------
----------------------------------------
Exception happened during processing of request from ('66.63.177.190', 61390)
Traceback (most recent call last):
  File "/usr/lib/python3.6/socketserver.py", line 654, in process_request_thread
    self.finish_request(request, client_address)
  File "/usr/lib/python3.6/socketserver.py", line 364, in finish_request
    self.RequestHandlerClass(request, client_address, self)
  File "/usr/lib/python3.6/socketserver.py", line 724, in __init__
    self.handle()
  File "/usr/local/lib/python3.6/dist-packages/django/core/servers/basehttp.py", line 172, in handle
    self.handle_one_request()
  File "/usr/local/lib/python3.6/dist-packages/django/core/servers/basehttp.py", line 182, in handle_one_request
    self.raw_requestline = self.rfile.readline(65537)
  File "/usr/lib/python3.6/socket.py", line 586, in readinto
    return self._sock.recv_into(b)
ConnectionResetError: [Errno 104] Connection reset by peer
----------------------------------------
Traceback (most recent call last):
  File "/usr/lib/python3.6/wsgiref/handlers.py", line 138, in run
    self.finish_response()
  File "/usr/lib/python3.6/wsgiref/handlers.py", line 180, in finish_response
    self.write(data)
  File "/usr/lib/python3.6/wsgiref/handlers.py", line 274, in write
    self.send_headers()
  File "/usr/lib/python3.6/wsgiref/handlers.py", line 332, in send_headers
    self.send_preamble()
  File "/usr/lib/python3.6/wsgiref/handlers.py", line 252, in send_preamble
    self._write(('HTTP/%s %s\r\n' % (self.http_version,self.status)).encode('iso-8859-1'))
  File "/usr/lib/python3.6/wsgiref/handlers.py", line 453, in _write
    result = self.stdout.write(data)
  File "/usr/lib/python3.6/socketserver.py", line 803, in write
    self._sock.sendall(b)
ConnectionResetError: [Errno 104] Connection reset by peer
----------------------------------------
Exception happened during processing of request from ('34.140.248.32', 33658)
Traceback (most recent call last):
  File "/usr/lib/python3.6/socketserver.py", line 654, in process_request_thread
    self.finish_request(request, client_address)
  File "/usr/lib/python3.6/socketserver.py", line 364, in finish_request
    self.RequestHandlerClass(request, client_address, self)
  File "/usr/lib/python3.6/socketserver.py", line 724, in __init__
    self.handle()
  File "/usr/local/lib/python3.6/dist-packages/django/core/servers/basehttp.py", line 174, in handle
    self.handle_one_request()
  File "/usr/local/lib/python3.6/dist-packages/django/core/servers/basehttp.py", line 182, in handle_one_request
    self.raw_requestline = self.rfile.readline(65537)
  File "/usr/lib/python3.6/socket.py", line 586, in readinto
    return self._sock.recv_into(b)
ConnectionResetError: [Errno 104] Connection reset by peer
----------------------------------------
----------------------------------------
Exception happened during processing of request from ('2.56.59.20', 43734)
Traceback (most recent call last):
  File "/usr/lib/python3.6/socketserver.py", line 654, in process_request_thread
    self.finish_request(request, client_address)
  File "/usr/lib/python3.6/socketserver.py", line 364, in finish_request
    self.RequestHandlerClass(request, client_address, self)
  File "/usr/lib/python3.6/socketserver.py", line 724, in __init__
    self.handle()
  File "/usr/local/lib/python3.6/dist-packages/django/core/servers/basehttp.py", line 174, in handle
    self.handle_one_request()
  File "/usr/local/lib/python3.6/dist-packages/django/core/servers/basehttp.py", line 182, in handle_one_request
    self.raw_requestline = self.rfile.readline(65537)
  File "/usr/lib/python3.6/socket.py", line 586, in readinto
    return self._sock.recv_into(b)
ConnectionResetError: [Errno 104] Connection reset by peer
----------------------------------------
Traceback (most recent call last):
  File "/usr/lib/python3.6/wsgiref/handlers.py", line 138, in run
    self.finish_response()
  File "/usr/lib/python3.6/wsgiref/handlers.py", line 183, in finish_response
    self.close()
  File "/usr/local/lib/python3.6/dist-packages/django/core/servers/basehttp.py", line 113, in close
    self.get_stdin()._read_limited()
  File "/usr/local/lib/python3.6/dist-packages/django/core/handlers/wsgi.py", line 28, in _read_limited
    result = self.stream.read(size)
  File "/usr/lib/python3.6/socket.py", line 586, in readinto
    return self._sock.recv_into(b)
ConnectionResetError: [Errno 104] Connection reset by peer
Traceback (most recent call last):
  File "/usr/lib/python3.6/wsgiref/handlers.py", line 138, in run
    self.finish_response()
  File "/usr/lib/python3.6/wsgiref/handlers.py", line 180, in finish_response
    self.write(data)
  File "/usr/lib/python3.6/wsgiref/handlers.py", line 274, in write
    self.send_headers()
  File "/usr/lib/python3.6/wsgiref/handlers.py", line 332, in send_headers
    self.send_preamble()
  File "/usr/lib/python3.6/wsgiref/handlers.py", line 252, in send_preamble
    self._write(('HTTP/%s %s\r\n' % (self.http_version,self.status)).encode('iso-8859-1'))
  File "/usr/lib/python3.6/wsgiref/handlers.py", line 453, in _write
    result = self.stdout.write(data)
  File "/usr/lib/python3.6/socketserver.py", line 803, in write
    self._sock.sendall(b)
ConnectionResetError: [Errno 104] Connection reset by peer
----------------------------------------
Exception happened during processing of request from ('92.118.234.202', 47816)
Traceback (most recent call last):
  File "/usr/lib/python3.6/wsgiref/handlers.py", line 138, in run
    self.finish_response()
  File "/usr/lib/python3.6/wsgiref/handlers.py", line 180, in finish_response
    self.write(data)
  File "/usr/lib/python3.6/wsgiref/handlers.py", line 274, in write
    self.send_headers()
  File "/usr/lib/python3.6/wsgiref/handlers.py", line 332, in send_headers
    self.send_preamble()
  File "/usr/lib/python3.6/wsgiref/handlers.py", line 252, in send_preamble
    self._write(('HTTP/%s %s\r\n' % (self.http_version,self.status)).encode('iso-8859-1'))
  File "/usr/lib/python3.6/wsgiref/handlers.py", line 453, in _write
    result = self.stdout.write(data)
  File "/usr/lib/python3.6/socketserver.py", line 803, in write
    self._sock.sendall(b)
ConnectionResetError: [Errno 104] Connection reset by peer

During handling of the above exception, another exception occurred:

Traceback (most recent call last):
  File "/usr/lib/python3.6/wsgiref/handlers.py", line 141, in run
    self.handle_error()
  File "/usr/local/lib/python3.6/dist-packages/django/core/servers/basehttp.py", line 119, in handle_error
    super().handle_error()
  File "/usr/lib/python3.6/wsgiref/handlers.py", line 368, in handle_error
    self.finish_response()
  File "/usr/lib/python3.6/wsgiref/handlers.py", line 180, in finish_response
    self.write(data)
  File "/usr/lib/python3.6/wsgiref/handlers.py", line 274, in write
    self.send_headers()
  File "/usr/lib/python3.6/wsgiref/handlers.py", line 331, in send_headers
    if not self.origin_server or self.client_is_modern():
  File "/usr/lib/python3.6/wsgiref/handlers.py", line 344, in client_is_modern
    return self.environ['SERVER_PROTOCOL'].upper() != 'HTTP/0.9'
TypeError: 'NoneType' object is not subscriptable

During handling of the above exception, another exception occurred:

Traceback (most recent call last):
  File "/usr/lib/python3.6/socketserver.py", line 654, in process_request_thread
    self.finish_request(request, client_address)
  File "/usr/lib/python3.6/socketserver.py", line 364, in finish_request
    self.RequestHandlerClass(request, client_address, self)
  File "/usr/lib/python3.6/socketserver.py", line 724, in __init__
    self.handle()
  File "/usr/local/lib/python3.6/dist-packages/django/core/servers/basehttp.py", line 172, in handle
    self.handle_one_request()
  File "/usr/local/lib/python3.6/dist-packages/django/core/servers/basehttp.py", line 197, in handle_one_request
    handler.run(self.server.get_app())
  File "/usr/lib/python3.6/wsgiref/handlers.py", line 144, in run
    self.close()
  File "/usr/local/lib/python3.6/dist-packages/django/core/servers/basehttp.py", line 114, in close
    super().close()
  File "/usr/lib/python3.6/wsgiref/simple_server.py", line 35, in close
    self.status.split(' ',1)[0], self.bytes_sent
AttributeError: 'NoneType' object has no attribute 'split'
----------------------------------------
Traceback (most recent call last):
  File "/usr/lib/python3.6/wsgiref/handlers.py", line 138, in run
    self.finish_response()
  File "/usr/lib/python3.6/wsgiref/handlers.py", line 180, in finish_response
    self.write(data)
  File "/usr/lib/python3.6/wsgiref/handlers.py", line 274, in write
    self.send_headers()
  File "/usr/lib/python3.6/wsgiref/handlers.py", line 332, in send_headers
    self.send_preamble()
  File "/usr/lib/python3.6/wsgiref/handlers.py", line 252, in send_preamble
    self._write(('HTTP/%s %s\r\n' % (self.http_version,self.status)).encode('iso-8859-1'))
  File "/usr/lib/python3.6/wsgiref/handlers.py", line 453, in _write
    result = self.stdout.write(data)
  File "/usr/lib/python3.6/socketserver.py", line 803, in write
    self._sock.sendall(b)
ConnectionResetError: [Errno 104] Connection reset by peer
----------------------------------------
Exception happened during processing of request from ('92.118.234.202', 49072)
Traceback (most recent call last):
  File "/usr/lib/python3.6/wsgiref/handlers.py", line 138, in run
    self.finish_response()
  File "/usr/lib/python3.6/wsgiref/handlers.py", line 180, in finish_response
    self.write(data)
  File "/usr/lib/python3.6/wsgiref/handlers.py", line 274, in write
    self.send_headers()
  File "/usr/lib/python3.6/wsgiref/handlers.py", line 332, in send_headers
    self.send_preamble()
  File "/usr/lib/python3.6/wsgiref/handlers.py", line 252, in send_preamble
    self._write(('HTTP/%s %s\r\n' % (self.http_version,self.status)).encode('iso-8859-1'))
  File "/usr/lib/python3.6/wsgiref/handlers.py", line 453, in _write
    result = self.stdout.write(data)
  File "/usr/lib/python3.6/socketserver.py", line 803, in write
    self._sock.sendall(b)
ConnectionResetError: [Errno 104] Connection reset by peer

During handling of the above exception, another exception occurred:

Traceback (most recent call last):
  File "/usr/lib/python3.6/wsgiref/handlers.py", line 141, in run
    self.handle_error()
  File "/usr/local/lib/python3.6/dist-packages/django/core/servers/basehttp.py", line 119, in handle_error
    super().handle_error()
  File "/usr/lib/python3.6/wsgiref/handlers.py", line 368, in handle_error
    self.finish_response()
  File "/usr/lib/python3.6/wsgiref/handlers.py", line 180, in finish_response
    self.write(data)
  File "/usr/lib/python3.6/wsgiref/handlers.py", line 274, in write
    self.send_headers()
  File "/usr/lib/python3.6/wsgiref/handlers.py", line 331, in send_headers
    if not self.origin_server or self.client_is_modern():
  File "/usr/lib/python3.6/wsgiref/handlers.py", line 344, in client_is_modern
    return self.environ['SERVER_PROTOCOL'].upper() != 'HTTP/0.9'
TypeError: 'NoneType' object is not subscriptable

During handling of the above exception, another exception occurred:

Traceback (most recent call last):
  File "/usr/lib/python3.6/socketserver.py", line 654, in process_request_thread
    self.finish_request(request, client_address)
  File "/usr/lib/python3.6/socketserver.py", line 364, in finish_request
    self.RequestHandlerClass(request, client_address, self)
  File "/usr/lib/python3.6/socketserver.py", line 724, in __init__
    self.handle()
  File "/usr/local/lib/python3.6/dist-packages/django/core/servers/basehttp.py", line 172, in handle
    self.handle_one_request()
  File "/usr/local/lib/python3.6/dist-packages/django/core/servers/basehttp.py", line 197, in handle_one_request
    handler.run(self.server.get_app())
  File "/usr/lib/python3.6/wsgiref/handlers.py", line 144, in run
    self.close()
  File "/usr/local/lib/python3.6/dist-packages/django/core/servers/basehttp.py", line 114, in close
    super().close()
  File "/usr/lib/python3.6/wsgiref/simple_server.py", line 35, in close
    self.status.split(' ',1)[0], self.bytes_sent
AttributeError: 'NoneType' object has no attribute 'split'
----------------------------------------
Traceback (most recent call last):
  File "/usr/lib/python3.6/wsgiref/handlers.py", line 138, in run
    self.finish_response()
  File "/usr/lib/python3.6/wsgiref/handlers.py", line 180, in finish_response
    self.write(data)
  File "/usr/lib/python3.6/wsgiref/handlers.py", line 274, in write
    self.send_headers()
  File "/usr/lib/python3.6/wsgiref/handlers.py", line 332, in send_headers
    self.send_preamble()
  File "/usr/lib/python3.6/wsgiref/handlers.py", line 252, in send_preamble
    self._write(('HTTP/%s %s\r\n' % (self.http_version,self.status)).encode('iso-8859-1'))
  File "/usr/lib/python3.6/wsgiref/handlers.py", line 453, in _write
    result = self.stdout.write(data)
  File "/usr/lib/python3.6/socketserver.py", line 803, in write
    self._sock.sendall(b)
ConnectionResetError: [Errno 104] Connection reset by peer
----------------------------------------
Exception happened during processing of request from ('45.137.21.208', 33252)
Traceback (most recent call last):
  File "/usr/lib/python3.6/wsgiref/handlers.py", line 138, in run
    self.finish_response()
  File "/usr/lib/python3.6/wsgiref/handlers.py", line 180, in finish_response
    self.write(data)
  File "/usr/lib/python3.6/wsgiref/handlers.py", line 274, in write
    self.send_headers()
  File "/usr/lib/python3.6/wsgiref/handlers.py", line 332, in send_headers
    self.send_preamble()
  File "/usr/lib/python3.6/wsgiref/handlers.py", line 252, in send_preamble
    self._write(('HTTP/%s %s\r\n' % (self.http_version,self.status)).encode('iso-8859-1'))
  File "/usr/lib/python3.6/wsgiref/handlers.py", line 453, in _write
    result = self.stdout.write(data)
  File "/usr/lib/python3.6/socketserver.py", line 803, in write
    self._sock.sendall(b)
ConnectionResetError: [Errno 104] Connection reset by peer

During handling of the above exception, another exception occurred:

Traceback (most recent call last):
  File "/usr/lib/python3.6/wsgiref/handlers.py", line 141, in run
    self.handle_error()
  File "/usr/local/lib/python3.6/dist-packages/django/core/servers/basehttp.py", line 119, in handle_error
    super().handle_error()
  File "/usr/lib/python3.6/wsgiref/handlers.py", line 368, in handle_error
    self.finish_response()
  File "/usr/lib/python3.6/wsgiref/handlers.py", line 180, in finish_response
    self.write(data)
  File "/usr/lib/python3.6/wsgiref/handlers.py", line 274, in write
    self.send_headers()
  File "/usr/lib/python3.6/wsgiref/handlers.py", line 331, in send_headers
    if not self.origin_server or self.client_is_modern():
  File "/usr/lib/python3.6/wsgiref/handlers.py", line 344, in client_is_modern
    return self.environ['SERVER_PROTOCOL'].upper() != 'HTTP/0.9'
TypeError: 'NoneType' object is not subscriptable

During handling of the above exception, another exception occurred:

Traceback (most recent call last):
  File "/usr/lib/python3.6/socketserver.py", line 654, in process_request_thread
    self.finish_request(request, client_address)
  File "/usr/lib/python3.6/socketserver.py", line 364, in finish_request
    self.RequestHandlerClass(request, client_address, self)
  File "/usr/lib/python3.6/socketserver.py", line 724, in __init__
    self.handle()
  File "/usr/local/lib/python3.6/dist-packages/django/core/servers/basehttp.py", line 172, in handle
    self.handle_one_request()
  File "/usr/local/lib/python3.6/dist-packages/django/core/servers/basehttp.py", line 197, in handle_one_request
    handler.run(self.server.get_app())
  File "/usr/lib/python3.6/wsgiref/handlers.py", line 144, in run
    self.close()
  File "/usr/local/lib/python3.6/dist-packages/django/core/servers/basehttp.py", line 114, in close
    super().close()
  File "/usr/lib/python3.6/wsgiref/simple_server.py", line 35, in close
    self.status.split(' ',1)[0], self.bytes_sent
AttributeError: 'NoneType' object has no attribute 'split'
----------------------------------------
Traceback (most recent call last):
  File "/usr/lib/python3.6/wsgiref/handlers.py", line 138, in run
    self.finish_response()
  File "/usr/lib/python3.6/wsgiref/handlers.py", line 180, in finish_response
    self.write(data)
  File "/usr/lib/python3.6/wsgiref/handlers.py", line 274, in write
    self.send_headers()
  File "/usr/lib/python3.6/wsgiref/handlers.py", line 332, in send_headers
    self.send_preamble()
  File "/usr/lib/python3.6/wsgiref/handlers.py", line 252, in send_preamble
    self._write(('HTTP/%s %s\r\n' % (self.http_version,self.status)).encode('iso-8859-1'))
  File "/usr/lib/python3.6/wsgiref/handlers.py", line 453, in _write
    result = self.stdout.write(data)
  File "/usr/lib/python3.6/socketserver.py", line 803, in write
    self._sock.sendall(b)
ConnectionResetError: [Errno 104] Connection reset by peer
----------------------------------------
Exception happened during processing of request from ('92.118.234.202', 41930)
Traceback (most recent call last):
  File "/usr/lib/python3.6/wsgiref/handlers.py", line 138, in run
    self.finish_response()
  File "/usr/lib/python3.6/wsgiref/handlers.py", line 180, in finish_response
    self.write(data)
  File "/usr/lib/python3.6/wsgiref/handlers.py", line 274, in write
    self.send_headers()
  File "/usr/lib/python3.6/wsgiref/handlers.py", line 332, in send_headers
    self.send_preamble()
  File "/usr/lib/python3.6/wsgiref/handlers.py", line 252, in send_preamble
    self._write(('HTTP/%s %s\r\n' % (self.http_version,self.status)).encode('iso-8859-1'))
  File "/usr/lib/python3.6/wsgiref/handlers.py", line 453, in _write
    result = self.stdout.write(data)
  File "/usr/lib/python3.6/socketserver.py", line 803, in write
    self._sock.sendall(b)
ConnectionResetError: [Errno 104] Connection reset by peer

During handling of the above exception, another exception occurred:

Traceback (most recent call last):
  File "/usr/lib/python3.6/wsgiref/handlers.py", line 141, in run
    self.handle_error()
  File "/usr/local/lib/python3.6/dist-packages/django/core/servers/basehttp.py", line 119, in handle_error
    super().handle_error()
  File "/usr/lib/python3.6/wsgiref/handlers.py", line 368, in handle_error
    self.finish_response()
  File "/usr/lib/python3.6/wsgiref/handlers.py", line 180, in finish_response
    self.write(data)
  File "/usr/lib/python3.6/wsgiref/handlers.py", line 274, in write
    self.send_headers()
  File "/usr/lib/python3.6/wsgiref/handlers.py", line 331, in send_headers
    if not self.origin_server or self.client_is_modern():
  File "/usr/lib/python3.6/wsgiref/handlers.py", line 344, in client_is_modern
    return self.environ['SERVER_PROTOCOL'].upper() != 'HTTP/0.9'
TypeError: 'NoneType' object is not subscriptable

During handling of the above exception, another exception occurred:

Traceback (most recent call last):
  File "/usr/lib/python3.6/socketserver.py", line 654, in process_request_thread
    self.finish_request(request, client_address)
  File "/usr/lib/python3.6/socketserver.py", line 364, in finish_request
    self.RequestHandlerClass(request, client_address, self)
  File "/usr/lib/python3.6/socketserver.py", line 724, in __init__
    self.handle()
  File "/usr/local/lib/python3.6/dist-packages/django/core/servers/basehttp.py", line 172, in handle
    self.handle_one_request()
  File "/usr/local/lib/python3.6/dist-packages/django/core/servers/basehttp.py", line 197, in handle_one_request
    handler.run(self.server.get_app())
  File "/usr/lib/python3.6/wsgiref/handlers.py", line 144, in run
    self.close()
  File "/usr/local/lib/python3.6/dist-packages/django/core/servers/basehttp.py", line 114, in close
    super().close()
  File "/usr/lib/python3.6/wsgiref/simple_server.py", line 35, in close
    self.status.split(' ',1)[0], self.bytes_sent
AttributeError: 'NoneType' object has no attribute 'split'
----------------------------------------
----------------------------------------
Exception happened during processing of request from ('167.94.138.62', 57708)
Traceback (most recent call last):
  File "/usr/lib/python3.6/socketserver.py", line 654, in process_request_thread
    self.finish_request(request, client_address)
  File "/usr/lib/python3.6/socketserver.py", line 364, in finish_request
    self.RequestHandlerClass(request, client_address, self)
  File "/usr/lib/python3.6/socketserver.py", line 724, in __init__
    self.handle()
  File "/usr/local/lib/python3.6/dist-packages/django/core/servers/basehttp.py", line 172, in handle
    self.handle_one_request()
  File "/usr/local/lib/python3.6/dist-packages/django/core/servers/basehttp.py", line 182, in handle_one_request
    self.raw_requestline = self.rfile.readline(65537)
  File "/usr/lib/python3.6/socket.py", line 586, in readinto
    return self._sock.recv_into(b)
ConnectionResetError: [Errno 104] Connection reset by peer
----------------------------------------
----------------------------------------
Exception happened during processing of request from ('167.94.138.62', 54506)
Traceback (most recent call last):
  File "/usr/lib/python3.6/socketserver.py", line 654, in process_request_thread
    self.finish_request(request, client_address)
  File "/usr/lib/python3.6/socketserver.py", line 364, in finish_request
    self.RequestHandlerClass(request, client_address, self)
  File "/usr/lib/python3.6/socketserver.py", line 724, in __init__
    self.handle()
  File "/usr/local/lib/python3.6/dist-packages/django/core/servers/basehttp.py", line 174, in handle
    self.handle_one_request()
  File "/usr/local/lib/python3.6/dist-packages/django/core/servers/basehttp.py", line 182, in handle_one_request
    self.raw_requestline = self.rfile.readline(65537)
  File "/usr/lib/python3.6/socket.py", line 586, in readinto
    return self._sock.recv_into(b)
ConnectionResetError: [Errno 104] Connection reset by peer
----------------------------------------
----------------------------------------
Exception happened during processing of request from ('89.248.164.165', 45562)
Traceback (most recent call last):
  File "/usr/lib/python3.6/socketserver.py", line 654, in process_request_thread
    self.finish_request(request, client_address)
  File "/usr/lib/python3.6/socketserver.py", line 364, in finish_request
    self.RequestHandlerClass(request, client_address, self)
  File "/usr/lib/python3.6/socketserver.py", line 724, in __init__
    self.handle()
  File "/usr/local/lib/python3.6/dist-packages/django/core/servers/basehttp.py", line 174, in handle
    self.handle_one_request()
  File "/usr/local/lib/python3.6/dist-packages/django/core/servers/basehttp.py", line 182, in handle_one_request
    self.raw_requestline = self.rfile.readline(65537)
  File "/usr/lib/python3.6/socket.py", line 586, in readinto
    return self._sock.recv_into(b)
ConnectionResetError: [Errno 104] Connection reset by peer
----------------------------------------
----------------------------------------
Exception happened during processing of request from ('58.255.203.131', 13462)
Traceback (most recent call last):
  File "/usr/lib/python3.6/socketserver.py", line 654, in process_request_thread
    self.finish_request(request, client_address)
  File "/usr/lib/python3.6/socketserver.py", line 364, in finish_request
    self.RequestHandlerClass(request, client_address, self)
  File "/usr/lib/python3.6/socketserver.py", line 724, in __init__
    self.handle()
  File "/usr/local/lib/python3.6/dist-packages/django/core/servers/basehttp.py", line 174, in handle
    self.handle_one_request()
  File "/usr/local/lib/python3.6/dist-packages/django/core/servers/basehttp.py", line 182, in handle_one_request
    self.raw_requestline = self.rfile.readline(65537)
  File "/usr/lib/python3.6/socket.py", line 586, in readinto
    return self._sock.recv_into(b)
ConnectionResetError: [Errno 104] Connection reset by peer
----------------------------------------
Traceback (most recent call last):
  File "/usr/lib/python3.6/wsgiref/handlers.py", line 138, in run
    self.finish_response()
  File "/usr/lib/python3.6/wsgiref/handlers.py", line 180, in finish_response
    self.write(data)
  File "/usr/lib/python3.6/wsgiref/handlers.py", line 274, in write
    self.send_headers()
  File "/usr/lib/python3.6/wsgiref/handlers.py", line 332, in send_headers
    self.send_preamble()
  File "/usr/lib/python3.6/wsgiref/handlers.py", line 252, in send_preamble
    self._write(('HTTP/%s %s\r\n' % (self.http_version,self.status)).encode('iso-8859-1'))
  File "/usr/lib/python3.6/wsgiref/handlers.py", line 453, in _write
    result = self.stdout.write(data)
  File "/usr/lib/python3.6/socketserver.py", line 803, in write
    self._sock.sendall(b)
ConnectionResetError: [Errno 104] Connection reset by peer
----------------------------------------
Exception happened during processing of request from ('167.248.133.46', 47786)
Traceback (most recent call last):
  File "/usr/lib/python3.6/socketserver.py", line 654, in process_request_thread
    self.finish_request(request, client_address)
  File "/usr/lib/python3.6/socketserver.py", line 364, in finish_request
    self.RequestHandlerClass(request, client_address, self)
  File "/usr/lib/python3.6/socketserver.py", line 724, in __init__
    self.handle()
  File "/usr/local/lib/python3.6/dist-packages/django/core/servers/basehttp.py", line 172, in handle
    self.handle_one_request()
  File "/usr/local/lib/python3.6/dist-packages/django/core/servers/basehttp.py", line 182, in handle_one_request
    self.raw_requestline = self.rfile.readline(65537)
  File "/usr/lib/python3.6/socket.py", line 586, in readinto
    return self._sock.recv_into(b)
ConnectionResetError: [Errno 104] Connection reset by peer
----------------------------------------
Traceback (most recent call last):
  File "/usr/lib/python3.6/wsgiref/handlers.py", line 138, in run
    self.finish_response()
  File "/usr/lib/python3.6/wsgiref/handlers.py", line 180, in finish_response
    self.write(data)
  File "/usr/lib/python3.6/wsgiref/handlers.py", line 274, in write
    self.send_headers()
  File "/usr/lib/python3.6/wsgiref/handlers.py", line 332, in send_headers
    self.send_preamble()
  File "/usr/lib/python3.6/wsgiref/handlers.py", line 252, in send_preamble
    self._write(('HTTP/%s %s\r\n' % (self.http_version,self.status)).encode('iso-8859-1'))
  File "/usr/lib/python3.6/wsgiref/handlers.py", line 453, in _write
    result = self.stdout.write(data)
  File "/usr/lib/python3.6/socketserver.py", line 803, in write
    self._sock.sendall(b)
ConnectionResetError: [Errno 104] Connection reset by peer
----------------------------------------
Exception happened during processing of request from ('92.118.234.202', 42602)
Traceback (most recent call last):
  File "/usr/lib/python3.6/wsgiref/handlers.py", line 138, in run
    self.finish_response()
  File "/usr/lib/python3.6/wsgiref/handlers.py", line 180, in finish_response
    self.write(data)
  File "/usr/lib/python3.6/wsgiref/handlers.py", line 274, in write
    self.send_headers()
  File "/usr/lib/python3.6/wsgiref/handlers.py", line 332, in send_headers
    self.send_preamble()
  File "/usr/lib/python3.6/wsgiref/handlers.py", line 252, in send_preamble
    self._write(('HTTP/%s %s\r\n' % (self.http_version,self.status)).encode('iso-8859-1'))
  File "/usr/lib/python3.6/wsgiref/handlers.py", line 453, in _write
    result = self.stdout.write(data)
  File "/usr/lib/python3.6/socketserver.py", line 803, in write
    self._sock.sendall(b)
ConnectionResetError: [Errno 104] Connection reset by peer

During handling of the above exception, another exception occurred:

Traceback (most recent call last):
  File "/usr/lib/python3.6/wsgiref/handlers.py", line 141, in run
    self.handle_error()
  File "/usr/local/lib/python3.6/dist-packages/django/core/servers/basehttp.py", line 119, in handle_error
    super().handle_error()
  File "/usr/lib/python3.6/wsgiref/handlers.py", line 368, in handle_error
    self.finish_response()
  File "/usr/lib/python3.6/wsgiref/handlers.py", line 180, in finish_response
    self.write(data)
  File "/usr/lib/python3.6/wsgiref/handlers.py", line 274, in write
    self.send_headers()
  File "/usr/lib/python3.6/wsgiref/handlers.py", line 331, in send_headers
    if not self.origin_server or self.client_is_modern():
  File "/usr/lib/python3.6/wsgiref/handlers.py", line 344, in client_is_modern
    return self.environ['SERVER_PROTOCOL'].upper() != 'HTTP/0.9'
TypeError: 'NoneType' object is not subscriptable

During handling of the above exception, another exception occurred:

Traceback (most recent call last):
  File "/usr/lib/python3.6/socketserver.py", line 654, in process_request_thread
    self.finish_request(request, client_address)
  File "/usr/lib/python3.6/socketserver.py", line 364, in finish_request
    self.RequestHandlerClass(request, client_address, self)
  File "/usr/lib/python3.6/socketserver.py", line 724, in __init__
    self.handle()
  File "/usr/local/lib/python3.6/dist-packages/django/core/servers/basehttp.py", line 172, in handle
    self.handle_one_request()
  File "/usr/local/lib/python3.6/dist-packages/django/core/servers/basehttp.py", line 197, in handle_one_request
    handler.run(self.server.get_app())
  File "/usr/lib/python3.6/wsgiref/handlers.py", line 144, in run
    self.close()
  File "/usr/local/lib/python3.6/dist-packages/django/core/servers/basehttp.py", line 114, in close
    super().close()
  File "/usr/lib/python3.6/wsgiref/simple_server.py", line 35, in close
    self.status.split(' ',1)[0], self.bytes_sent
AttributeError: 'NoneType' object has no attribute 'split'
----------------------------------------
----------------------------------------
Exception happened during processing of request from ('2.56.59.20', 39186)
Traceback (most recent call last):
  File "/usr/lib/python3.6/socketserver.py", line 654, in process_request_thread
    self.finish_request(request, client_address)
  File "/usr/lib/python3.6/socketserver.py", line 364, in finish_request
    self.RequestHandlerClass(request, client_address, self)
  File "/usr/lib/python3.6/socketserver.py", line 724, in __init__
    self.handle()
  File "/usr/local/lib/python3.6/dist-packages/django/core/servers/basehttp.py", line 174, in handle
    self.handle_one_request()
  File "/usr/local/lib/python3.6/dist-packages/django/core/servers/basehttp.py", line 182, in handle_one_request
    self.raw_requestline = self.rfile.readline(65537)
  File "/usr/lib/python3.6/socket.py", line 586, in readinto
    return self._sock.recv_into(b)
ConnectionResetError: [Errno 104] Connection reset by peer
----------------------------------------
Traceback (most recent call last):
  File "/usr/lib/python3.6/wsgiref/handlers.py", line 138, in run
    self.finish_response()
  File "/usr/lib/python3.6/wsgiref/handlers.py", line 183, in finish_response
    self.close()
  File "/usr/local/lib/python3.6/dist-packages/django/core/servers/basehttp.py", line 113, in close
    self.get_stdin()._read_limited()
  File "/usr/local/lib/python3.6/dist-packages/django/core/handlers/wsgi.py", line 28, in _read_limited
    result = self.stream.read(size)
  File "/usr/lib/python3.6/socket.py", line 586, in readinto
    return self._sock.recv_into(b)
ConnectionResetError: [Errno 104] Connection reset by peer
Traceback (most recent call last):
  File "/usr/lib/python3.6/wsgiref/handlers.py", line 138, in run
    self.finish_response()
  File "/usr/lib/python3.6/wsgiref/handlers.py", line 180, in finish_response
    self.write(data)
  File "/usr/lib/python3.6/wsgiref/handlers.py", line 274, in write
    self.send_headers()
  File "/usr/lib/python3.6/wsgiref/handlers.py", line 332, in send_headers
    self.send_preamble()
  File "/usr/lib/python3.6/wsgiref/handlers.py", line 252, in send_preamble
    self._write(('HTTP/%s %s\r\n' % (self.http_version,self.status)).encode('iso-8859-1'))
  File "/usr/lib/python3.6/wsgiref/handlers.py", line 453, in _write
    result = self.stdout.write(data)
  File "/usr/lib/python3.6/socketserver.py", line 803, in write
    self._sock.sendall(b)
ConnectionResetError: [Errno 104] Connection reset by peer
----------------------------------------
Exception happened during processing of request from ('92.118.234.202', 54532)
Traceback (most recent call last):
  File "/usr/lib/python3.6/wsgiref/handlers.py", line 138, in run
    self.finish_response()
  File "/usr/lib/python3.6/wsgiref/handlers.py", line 180, in finish_response
    self.write(data)
  File "/usr/lib/python3.6/wsgiref/handlers.py", line 274, in write
    self.send_headers()
  File "/usr/lib/python3.6/wsgiref/handlers.py", line 332, in send_headers
    self.send_preamble()
  File "/usr/lib/python3.6/wsgiref/handlers.py", line 252, in send_preamble
    self._write(('HTTP/%s %s\r\n' % (self.http_version,self.status)).encode('iso-8859-1'))
  File "/usr/lib/python3.6/wsgiref/handlers.py", line 453, in _write
    result = self.stdout.write(data)
  File "/usr/lib/python3.6/socketserver.py", line 803, in write
    self._sock.sendall(b)
ConnectionResetError: [Errno 104] Connection reset by peer

During handling of the above exception, another exception occurred:

Traceback (most recent call last):
  File "/usr/lib/python3.6/wsgiref/handlers.py", line 141, in run
    self.handle_error()
  File "/usr/local/lib/python3.6/dist-packages/django/core/servers/basehttp.py", line 119, in handle_error
    super().handle_error()
  File "/usr/lib/python3.6/wsgiref/handlers.py", line 368, in handle_error
    self.finish_response()
  File "/usr/lib/python3.6/wsgiref/handlers.py", line 180, in finish_response
    self.write(data)
  File "/usr/lib/python3.6/wsgiref/handlers.py", line 274, in write
    self.send_headers()
  File "/usr/lib/python3.6/wsgiref/handlers.py", line 331, in send_headers
    if not self.origin_server or self.client_is_modern():
  File "/usr/lib/python3.6/wsgiref/handlers.py", line 344, in client_is_modern
    return self.environ['SERVER_PROTOCOL'].upper() != 'HTTP/0.9'
TypeError: 'NoneType' object is not subscriptable

During handling of the above exception, another exception occurred:

Traceback (most recent call last):
  File "/usr/lib/python3.6/socketserver.py", line 654, in process_request_thread
    self.finish_request(request, client_address)
  File "/usr/lib/python3.6/socketserver.py", line 364, in finish_request
    self.RequestHandlerClass(request, client_address, self)
  File "/usr/lib/python3.6/socketserver.py", line 724, in __init__
    self.handle()
  File "/usr/local/lib/python3.6/dist-packages/django/core/servers/basehttp.py", line 172, in handle
    self.handle_one_request()
  File "/usr/local/lib/python3.6/dist-packages/django/core/servers/basehttp.py", line 197, in handle_one_request
    handler.run(self.server.get_app())
  File "/usr/lib/python3.6/wsgiref/handlers.py", line 144, in run
    self.close()
  File "/usr/local/lib/python3.6/dist-packages/django/core/servers/basehttp.py", line 114, in close
    super().close()
  File "/usr/lib/python3.6/wsgiref/simple_server.py", line 35, in close
    self.status.split(' ',1)[0], self.bytes_sent
AttributeError: 'NoneType' object has no attribute 'split'
----------------------------------------
Traceback (most recent call last):
  File "/usr/lib/python3.6/wsgiref/handlers.py", line 138, in run
    self.finish_response()
  File "/usr/lib/python3.6/wsgiref/handlers.py", line 180, in finish_response
    self.write(data)
  File "/usr/lib/python3.6/wsgiref/handlers.py", line 274, in write
    self.send_headers()
  File "/usr/lib/python3.6/wsgiref/handlers.py", line 332, in send_headers
    self.send_preamble()
  File "/usr/lib/python3.6/wsgiref/handlers.py", line 252, in send_preamble
    self._write(('HTTP/%s %s\r\n' % (self.http_version,self.status)).encode('iso-8859-1'))
  File "/usr/lib/python3.6/wsgiref/handlers.py", line 453, in _write
    result = self.stdout.write(data)
  File "/usr/lib/python3.6/socketserver.py", line 803, in write
    self._sock.sendall(b)
ConnectionResetError: [Errno 104] Connection reset by peer
----------------------------------------
Exception happened during processing of request from ('92.118.234.202', 50172)
Traceback (most recent call last):
  File "/usr/lib/python3.6/wsgiref/handlers.py", line 138, in run
    self.finish_response()
  File "/usr/lib/python3.6/wsgiref/handlers.py", line 180, in finish_response
    self.write(data)
  File "/usr/lib/python3.6/wsgiref/handlers.py", line 274, in write
    self.send_headers()
  File "/usr/lib/python3.6/wsgiref/handlers.py", line 332, in send_headers
    self.send_preamble()
  File "/usr/lib/python3.6/wsgiref/handlers.py", line 252, in send_preamble
    self._write(('HTTP/%s %s\r\n' % (self.http_version,self.status)).encode('iso-8859-1'))
  File "/usr/lib/python3.6/wsgiref/handlers.py", line 453, in _write
    result = self.stdout.write(data)
  File "/usr/lib/python3.6/socketserver.py", line 803, in write
    self._sock.sendall(b)
ConnectionResetError: [Errno 104] Connection reset by peer

During handling of the above exception, another exception occurred:

Traceback (most recent call last):
  File "/usr/lib/python3.6/wsgiref/handlers.py", line 141, in run
    self.handle_error()
  File "/usr/local/lib/python3.6/dist-packages/django/core/servers/basehttp.py", line 119, in handle_error
    super().handle_error()
  File "/usr/lib/python3.6/wsgiref/handlers.py", line 368, in handle_error
    self.finish_response()
  File "/usr/lib/python3.6/wsgiref/handlers.py", line 180, in finish_response
    self.write(data)
  File "/usr/lib/python3.6/wsgiref/handlers.py", line 274, in write
    self.send_headers()
  File "/usr/lib/python3.6/wsgiref/handlers.py", line 331, in send_headers
    if not self.origin_server or self.client_is_modern():
  File "/usr/lib/python3.6/wsgiref/handlers.py", line 344, in client_is_modern
    return self.environ['SERVER_PROTOCOL'].upper() != 'HTTP/0.9'
TypeError: 'NoneType' object is not subscriptable

During handling of the above exception, another exception occurred:

Traceback (most recent call last):
  File "/usr/lib/python3.6/socketserver.py", line 654, in process_request_thread
    self.finish_request(request, client_address)
  File "/usr/lib/python3.6/socketserver.py", line 364, in finish_request
    self.RequestHandlerClass(request, client_address, self)
  File "/usr/lib/python3.6/socketserver.py", line 724, in __init__
    self.handle()
  File "/usr/local/lib/python3.6/dist-packages/django/core/servers/basehttp.py", line 172, in handle
    self.handle_one_request()
  File "/usr/local/lib/python3.6/dist-packages/django/core/servers/basehttp.py", line 197, in handle_one_request
    handler.run(self.server.get_app())
  File "/usr/lib/python3.6/wsgiref/handlers.py", line 144, in run
    self.close()
  File "/usr/local/lib/python3.6/dist-packages/django/core/servers/basehttp.py", line 114, in close
    super().close()
  File "/usr/lib/python3.6/wsgiref/simple_server.py", line 35, in close
    self.status.split(' ',1)[0], self.bytes_sent
AttributeError: 'NoneType' object has no attribute 'split'
----------------------------------------
Traceback (most recent call last):
  File "/usr/lib/python3.6/wsgiref/handlers.py", line 138, in run
    self.finish_response()
  File "/usr/lib/python3.6/wsgiref/handlers.py", line 180, in finish_response
    self.write(data)
  File "/usr/lib/python3.6/wsgiref/handlers.py", line 274, in write
    self.send_headers()
  File "/usr/lib/python3.6/wsgiref/handlers.py", line 332, in send_headers
    self.send_preamble()
  File "/usr/lib/python3.6/wsgiref/handlers.py", line 252, in send_preamble
    self._write(('HTTP/%s %s\r\n' % (self.http_version,self.status)).encode('iso-8859-1'))
  File "/usr/lib/python3.6/wsgiref/handlers.py", line 453, in _write
    result = self.stdout.write(data)
  File "/usr/lib/python3.6/socketserver.py", line 803, in write
    self._sock.sendall(b)
ConnectionResetError: [Errno 104] Connection reset by peer
Traceback (most recent call last):
  File "/usr/lib/python3.6/wsgiref/handlers.py", line 138, in run
    self.finish_response()
  File "/usr/lib/python3.6/wsgiref/handlers.py", line 180, in finish_response
    self.write(data)
  File "/usr/lib/python3.6/wsgiref/handlers.py", line 274, in write
    self.send_headers()
  File "/usr/lib/python3.6/wsgiref/handlers.py", line 332, in send_headers
    self.send_preamble()
  File "/usr/lib/python3.6/wsgiref/handlers.py", line 252, in send_preamble
    self._write(('HTTP/%s %s\r\n' % (self.http_version,self.status)).encode('iso-8859-1'))
  File "/usr/lib/python3.6/wsgiref/handlers.py", line 453, in _write
    result = self.stdout.write(data)
  File "/usr/lib/python3.6/socketserver.py", line 803, in write
    self._sock.sendall(b)
ConnectionResetError: [Errno 104] Connection reset by peer
----------------------------------------
Exception happened during processing of request from ('92.118.234.202', 51682)
Traceback (most recent call last):
  File "/usr/lib/python3.6/wsgiref/handlers.py", line 138, in run
    self.finish_response()
  File "/usr/lib/python3.6/wsgiref/handlers.py", line 180, in finish_response
    self.write(data)
  File "/usr/lib/python3.6/wsgiref/handlers.py", line 274, in write
    self.send_headers()
  File "/usr/lib/python3.6/wsgiref/handlers.py", line 332, in send_headers
    self.send_preamble()
  File "/usr/lib/python3.6/wsgiref/handlers.py", line 252, in send_preamble
    self._write(('HTTP/%s %s\r\n' % (self.http_version,self.status)).encode('iso-8859-1'))
  File "/usr/lib/python3.6/wsgiref/handlers.py", line 453, in _write
    result = self.stdout.write(data)
  File "/usr/lib/python3.6/socketserver.py", line 803, in write
    self._sock.sendall(b)
ConnectionResetError: [Errno 104] Connection reset by peer

During handling of the above exception, another exception occurred:

Traceback (most recent call last):
  File "/usr/lib/python3.6/wsgiref/handlers.py", line 141, in run
    self.handle_error()
  File "/usr/local/lib/python3.6/dist-packages/django/core/servers/basehttp.py", line 119, in handle_error
    super().handle_error()
  File "/usr/lib/python3.6/wsgiref/handlers.py", line 368, in handle_error
    self.finish_response()
  File "/usr/lib/python3.6/wsgiref/handlers.py", line 180, in finish_response
    self.write(data)
  File "/usr/lib/python3.6/wsgiref/handlers.py", line 274, in write
    self.send_headers()
  File "/usr/lib/python3.6/wsgiref/handlers.py", line 331, in send_headers
    if not self.origin_server or self.client_is_modern():
  File "/usr/lib/python3.6/wsgiref/handlers.py", line 344, in client_is_modern
    return self.environ['SERVER_PROTOCOL'].upper() != 'HTTP/0.9'
TypeError: 'NoneType' object is not subscriptable

During handling of the above exception, another exception occurred:

Traceback (most recent call last):
  File "/usr/lib/python3.6/socketserver.py", line 654, in process_request_thread
    self.finish_request(request, client_address)
  File "/usr/lib/python3.6/socketserver.py", line 364, in finish_request
    self.RequestHandlerClass(request, client_address, self)
  File "/usr/lib/python3.6/socketserver.py", line 724, in __init__
    self.handle()
  File "/usr/local/lib/python3.6/dist-packages/django/core/servers/basehttp.py", line 172, in handle
    self.handle_one_request()
  File "/usr/local/lib/python3.6/dist-packages/django/core/servers/basehttp.py", line 197, in handle_one_request
    handler.run(self.server.get_app())
  File "/usr/lib/python3.6/wsgiref/handlers.py", line 144, in run
    self.close()
  File "/usr/local/lib/python3.6/dist-packages/django/core/servers/basehttp.py", line 114, in close
    super().close()
  File "/usr/lib/python3.6/wsgiref/simple_server.py", line 35, in close
    self.status.split(' ',1)[0], self.bytes_sent
AttributeError: 'NoneType' object has no attribute 'split'
----------------------------------------
----------------------------------------
Exception happened during processing of request from ('123.130.229.95', 57995)
Traceback (most recent call last):
  File "/usr/lib/python3.6/socketserver.py", line 654, in process_request_thread
    self.finish_request(request, client_address)
  File "/usr/lib/python3.6/socketserver.py", line 364, in finish_request
    self.RequestHandlerClass(request, client_address, self)
  File "/usr/lib/python3.6/socketserver.py", line 724, in __init__
    self.handle()
  File "/usr/local/lib/python3.6/dist-packages/django/core/servers/basehttp.py", line 174, in handle
    self.handle_one_request()
  File "/usr/local/lib/python3.6/dist-packages/django/core/servers/basehttp.py", line 182, in handle_one_request
    self.raw_requestline = self.rfile.readline(65537)
  File "/usr/lib/python3.6/socket.py", line 586, in readinto
    return self._sock.recv_into(b)
ConnectionResetError: [Errno 104] Connection reset by peer
----------------------------------------
Traceback (most recent call last):
  File "/usr/lib/python3.6/wsgiref/handlers.py", line 138, in run
    self.finish_response()
  File "/usr/lib/python3.6/wsgiref/handlers.py", line 180, in finish_response
    self.write(data)
  File "/usr/lib/python3.6/wsgiref/handlers.py", line 274, in write
    self.send_headers()
  File "/usr/lib/python3.6/wsgiref/handlers.py", line 332, in send_headers
    self.send_preamble()
  File "/usr/lib/python3.6/wsgiref/handlers.py", line 252, in send_preamble
    self._write(('HTTP/%s %s\r\n' % (self.http_version,self.status)).encode('iso-8859-1'))
  File "/usr/lib/python3.6/wsgiref/handlers.py", line 453, in _write
    result = self.stdout.write(data)
  File "/usr/lib/python3.6/socketserver.py", line 803, in write
    self._sock.sendall(b)
ConnectionResetError: [Errno 104] Connection reset by peer
----------------------------------------
Exception happened during processing of request from ('92.118.234.202', 42012)
Traceback (most recent call last):
  File "/usr/lib/python3.6/wsgiref/handlers.py", line 138, in run
    self.finish_response()
  File "/usr/lib/python3.6/wsgiref/handlers.py", line 180, in finish_response
    self.write(data)
  File "/usr/lib/python3.6/wsgiref/handlers.py", line 274, in write
    self.send_headers()
  File "/usr/lib/python3.6/wsgiref/handlers.py", line 332, in send_headers
    self.send_preamble()
  File "/usr/lib/python3.6/wsgiref/handlers.py", line 252, in send_preamble
    self._write(('HTTP/%s %s\r\n' % (self.http_version,self.status)).encode('iso-8859-1'))
  File "/usr/lib/python3.6/wsgiref/handlers.py", line 453, in _write
    result = self.stdout.write(data)
  File "/usr/lib/python3.6/socketserver.py", line 803, in write
    self._sock.sendall(b)
ConnectionResetError: [Errno 104] Connection reset by peer

During handling of the above exception, another exception occurred:

Traceback (most recent call last):
  File "/usr/lib/python3.6/wsgiref/handlers.py", line 141, in run
    self.handle_error()
  File "/usr/local/lib/python3.6/dist-packages/django/core/servers/basehttp.py", line 119, in handle_error
    super().handle_error()
  File "/usr/lib/python3.6/wsgiref/handlers.py", line 368, in handle_error
    self.finish_response()
  File "/usr/lib/python3.6/wsgiref/handlers.py", line 180, in finish_response
    self.write(data)
  File "/usr/lib/python3.6/wsgiref/handlers.py", line 274, in write
    self.send_headers()
  File "/usr/lib/python3.6/wsgiref/handlers.py", line 331, in send_headers
    if not self.origin_server or self.client_is_modern():
  File "/usr/lib/python3.6/wsgiref/handlers.py", line 344, in client_is_modern
    return self.environ['SERVER_PROTOCOL'].upper() != 'HTTP/0.9'
TypeError: 'NoneType' object is not subscriptable

During handling of the above exception, another exception occurred:

Traceback (most recent call last):
  File "/usr/lib/python3.6/socketserver.py", line 654, in process_request_thread
    self.finish_request(request, client_address)
  File "/usr/lib/python3.6/socketserver.py", line 364, in finish_request
    self.RequestHandlerClass(request, client_address, self)
  File "/usr/lib/python3.6/socketserver.py", line 724, in __init__
    self.handle()
  File "/usr/local/lib/python3.6/dist-packages/django/core/servers/basehttp.py", line 172, in handle
    self.handle_one_request()
  File "/usr/local/lib/python3.6/dist-packages/django/core/servers/basehttp.py", line 197, in handle_one_request
    handler.run(self.server.get_app())
  File "/usr/lib/python3.6/wsgiref/handlers.py", line 144, in run
    self.close()
  File "/usr/local/lib/python3.6/dist-packages/django/core/servers/basehttp.py", line 114, in close
    super().close()
  File "/usr/lib/python3.6/wsgiref/simple_server.py", line 35, in close
    self.status.split(' ',1)[0], self.bytes_sent
AttributeError: 'NoneType' object has no attribute 'split'
----------------------------------------
----------------------------------------
Exception happened during processing of request from ('185.189.182.234', 43524)
Traceback (most recent call last):
  File "/usr/lib/python3.6/socketserver.py", line 654, in process_request_thread
    self.finish_request(request, client_address)
  File "/usr/lib/python3.6/socketserver.py", line 364, in finish_request
    self.RequestHandlerClass(request, client_address, self)
  File "/usr/lib/python3.6/socketserver.py", line 724, in __init__
    self.handle()
  File "/usr/local/lib/python3.6/dist-packages/django/core/servers/basehttp.py", line 174, in handle
    self.handle_one_request()
  File "/usr/local/lib/python3.6/dist-packages/django/core/servers/basehttp.py", line 182, in handle_one_request
    self.raw_requestline = self.rfile.readline(65537)
  File "/usr/lib/python3.6/socket.py", line 586, in readinto
    return self._sock.recv_into(b)
ConnectionResetError: [Errno 104] Connection reset by peer
----------------------------------------
----------------------------------------
Exception happened during processing of request from ('49.143.32.6', 1837)
Traceback (most recent call last):
  File "/usr/lib/python3.6/socketserver.py", line 654, in process_request_thread
    self.finish_request(request, client_address)
  File "/usr/lib/python3.6/socketserver.py", line 364, in finish_request
    self.RequestHandlerClass(request, client_address, self)
  File "/usr/lib/python3.6/socketserver.py", line 724, in __init__
    self.handle()
  File "/usr/local/lib/python3.6/dist-packages/django/core/servers/basehttp.py", line 174, in handle
    self.handle_one_request()
  File "/usr/local/lib/python3.6/dist-packages/django/core/servers/basehttp.py", line 182, in handle_one_request
    self.raw_requestline = self.rfile.readline(65537)
  File "/usr/lib/python3.6/socket.py", line 586, in readinto
    return self._sock.recv_into(b)
ConnectionResetError: [Errno 104] Connection reset by peer
----------------------------------------
Traceback (most recent call last):
  File "/usr/lib/python3.6/wsgiref/handlers.py", line 138, in run
    self.finish_response()
  File "/usr/lib/python3.6/wsgiref/handlers.py", line 180, in finish_response
    self.write(data)
  File "/usr/lib/python3.6/wsgiref/handlers.py", line 274, in write
    self.send_headers()
  File "/usr/lib/python3.6/wsgiref/handlers.py", line 332, in send_headers
    self.send_preamble()
  File "/usr/lib/python3.6/wsgiref/handlers.py", line 252, in send_preamble
    self._write(('HTTP/%s %s\r\n' % (self.http_version,self.status)).encode('iso-8859-1'))
  File "/usr/lib/python3.6/wsgiref/handlers.py", line 453, in _write
    result = self.stdout.write(data)
  File "/usr/lib/python3.6/socketserver.py", line 803, in write
    self._sock.sendall(b)
ConnectionResetError: [Errno 104] Connection reset by peer
----------------------------------------
Exception happened during processing of request from ('92.118.234.202', 34074)
Traceback (most recent call last):
  File "/usr/lib/python3.6/wsgiref/handlers.py", line 138, in run
    self.finish_response()
  File "/usr/lib/python3.6/wsgiref/handlers.py", line 180, in finish_response
    self.write(data)
  File "/usr/lib/python3.6/wsgiref/handlers.py", line 274, in write
    self.send_headers()
  File "/usr/lib/python3.6/wsgiref/handlers.py", line 332, in send_headers
    self.send_preamble()
  File "/usr/lib/python3.6/wsgiref/handlers.py", line 252, in send_preamble
    self._write(('HTTP/%s %s\r\n' % (self.http_version,self.status)).encode('iso-8859-1'))
  File "/usr/lib/python3.6/wsgiref/handlers.py", line 453, in _write
    result = self.stdout.write(data)
  File "/usr/lib/python3.6/socketserver.py", line 803, in write
    self._sock.sendall(b)
ConnectionResetError: [Errno 104] Connection reset by peer

During handling of the above exception, another exception occurred:

Traceback (most recent call last):
  File "/usr/lib/python3.6/wsgiref/handlers.py", line 141, in run
    self.handle_error()
  File "/usr/local/lib/python3.6/dist-packages/django/core/servers/basehttp.py", line 119, in handle_error
    super().handle_error()
  File "/usr/lib/python3.6/wsgiref/handlers.py", line 368, in handle_error
    self.finish_response()
  File "/usr/lib/python3.6/wsgiref/handlers.py", line 180, in finish_response
    self.write(data)
  File "/usr/lib/python3.6/wsgiref/handlers.py", line 274, in write
    self.send_headers()
  File "/usr/lib/python3.6/wsgiref/handlers.py", line 331, in send_headers
    if not self.origin_server or self.client_is_modern():
  File "/usr/lib/python3.6/wsgiref/handlers.py", line 344, in client_is_modern
    return self.environ['SERVER_PROTOCOL'].upper() != 'HTTP/0.9'
TypeError: 'NoneType' object is not subscriptable

During handling of the above exception, another exception occurred:

Traceback (most recent call last):
  File "/usr/lib/python3.6/socketserver.py", line 654, in process_request_thread
    self.finish_request(request, client_address)
  File "/usr/lib/python3.6/socketserver.py", line 364, in finish_request
    self.RequestHandlerClass(request, client_address, self)
  File "/usr/lib/python3.6/socketserver.py", line 724, in __init__
    self.handle()
  File "/usr/local/lib/python3.6/dist-packages/django/core/servers/basehttp.py", line 172, in handle
    self.handle_one_request()
  File "/usr/local/lib/python3.6/dist-packages/django/core/servers/basehttp.py", line 197, in handle_one_request
    handler.run(self.server.get_app())
  File "/usr/lib/python3.6/wsgiref/handlers.py", line 144, in run
    self.close()
  File "/usr/local/lib/python3.6/dist-packages/django/core/servers/basehttp.py", line 114, in close
    super().close()
  File "/usr/lib/python3.6/wsgiref/simple_server.py", line 35, in close
    self.status.split(' ',1)[0], self.bytes_sent
AttributeError: 'NoneType' object has no attribute 'split'
----------------------------------------
Traceback (most recent call last):
  File "/usr/lib/python3.6/wsgiref/handlers.py", line 138, in run
    self.finish_response()
  File "/usr/lib/python3.6/wsgiref/handlers.py", line 180, in finish_response
    self.write(data)
  File "/usr/lib/python3.6/wsgiref/handlers.py", line 274, in write
    self.send_headers()
  File "/usr/lib/python3.6/wsgiref/handlers.py", line 332, in send_headers
    self.send_preamble()
  File "/usr/lib/python3.6/wsgiref/handlers.py", line 252, in send_preamble
    self._write(('HTTP/%s %s\r\n' % (self.http_version,self.status)).encode('iso-8859-1'))
  File "/usr/lib/python3.6/wsgiref/handlers.py", line 453, in _write
    result = self.stdout.write(data)
  File "/usr/lib/python3.6/socketserver.py", line 803, in write
    self._sock.sendall(b)
ConnectionResetError: [Errno 104] Connection reset by peer
----------------------------------------
Exception happened during processing of request from ('92.118.234.202', 44320)
Traceback (most recent call last):
  File "/usr/lib/python3.6/wsgiref/handlers.py", line 138, in run
    self.finish_response()
  File "/usr/lib/python3.6/wsgiref/handlers.py", line 180, in finish_response
    self.write(data)
  File "/usr/lib/python3.6/wsgiref/handlers.py", line 274, in write
    self.send_headers()
  File "/usr/lib/python3.6/wsgiref/handlers.py", line 332, in send_headers
    self.send_preamble()
  File "/usr/lib/python3.6/wsgiref/handlers.py", line 252, in send_preamble
    self._write(('HTTP/%s %s\r\n' % (self.http_version,self.status)).encode('iso-8859-1'))
  File "/usr/lib/python3.6/wsgiref/handlers.py", line 453, in _write
    result = self.stdout.write(data)
  File "/usr/lib/python3.6/socketserver.py", line 803, in write
    self._sock.sendall(b)
ConnectionResetError: [Errno 104] Connection reset by peer

During handling of the above exception, another exception occurred:

Traceback (most recent call last):
  File "/usr/lib/python3.6/wsgiref/handlers.py", line 141, in run
    self.handle_error()
  File "/usr/local/lib/python3.6/dist-packages/django/core/servers/basehttp.py", line 119, in handle_error
    super().handle_error()
  File "/usr/lib/python3.6/wsgiref/handlers.py", line 368, in handle_error
    self.finish_response()
  File "/usr/lib/python3.6/wsgiref/handlers.py", line 180, in finish_response
    self.write(data)
  File "/usr/lib/python3.6/wsgiref/handlers.py", line 274, in write
    self.send_headers()
  File "/usr/lib/python3.6/wsgiref/handlers.py", line 331, in send_headers
    if not self.origin_server or self.client_is_modern():
  File "/usr/lib/python3.6/wsgiref/handlers.py", line 344, in client_is_modern
    return self.environ['SERVER_PROTOCOL'].upper() != 'HTTP/0.9'
TypeError: 'NoneType' object is not subscriptable

During handling of the above exception, another exception occurred:

Traceback (most recent call last):
  File "/usr/lib/python3.6/socketserver.py", line 654, in process_request_thread
    self.finish_request(request, client_address)
  File "/usr/lib/python3.6/socketserver.py", line 364, in finish_request
    self.RequestHandlerClass(request, client_address, self)
  File "/usr/lib/python3.6/socketserver.py", line 724, in __init__
    self.handle()
  File "/usr/local/lib/python3.6/dist-packages/django/core/servers/basehttp.py", line 172, in handle
    self.handle_one_request()
  File "/usr/local/lib/python3.6/dist-packages/django/core/servers/basehttp.py", line 197, in handle_one_request
    handler.run(self.server.get_app())
  File "/usr/lib/python3.6/wsgiref/handlers.py", line 144, in run
    self.close()
  File "/usr/local/lib/python3.6/dist-packages/django/core/servers/basehttp.py", line 114, in close
    super().close()
  File "/usr/lib/python3.6/wsgiref/simple_server.py", line 35, in close
    self.status.split(' ',1)[0], self.bytes_sent
AttributeError: 'NoneType' object has no attribute 'split'
----------------------------------------
----------------------------------------
Exception happened during processing of request from ('106.12.3.163', 55472)
Traceback (most recent call last):
  File "/usr/lib/python3.6/socketserver.py", line 654, in process_request_thread
    self.finish_request(request, client_address)
  File "/usr/lib/python3.6/socketserver.py", line 364, in finish_request
    self.RequestHandlerClass(request, client_address, self)
  File "/usr/lib/python3.6/socketserver.py", line 724, in __init__
    self.handle()
  File "/usr/local/lib/python3.6/dist-packages/django/core/servers/basehttp.py", line 174, in handle
    self.handle_one_request()
  File "/usr/local/lib/python3.6/dist-packages/django/core/servers/basehttp.py", line 182, in handle_one_request
    self.raw_requestline = self.rfile.readline(65537)
  File "/usr/lib/python3.6/socket.py", line 586, in readinto
    return self._sock.recv_into(b)
ConnectionResetError: [Errno 104] Connection reset by peer
----------------------------------------
----------------------------------------
Exception happened during processing of request from ('106.12.3.163', 51724)
Traceback (most recent call last):
  File "/usr/lib/python3.6/socketserver.py", line 654, in process_request_thread
    self.finish_request(request, client_address)
  File "/usr/lib/python3.6/socketserver.py", line 364, in finish_request
    self.RequestHandlerClass(request, client_address, self)
  File "/usr/lib/python3.6/socketserver.py", line 724, in __init__
    self.handle()
  File "/usr/local/lib/python3.6/dist-packages/django/core/servers/basehttp.py", line 174, in handle
    self.handle_one_request()
  File "/usr/local/lib/python3.6/dist-packages/django/core/servers/basehttp.py", line 182, in handle_one_request
    self.raw_requestline = self.rfile.readline(65537)
  File "/usr/lib/python3.6/socket.py", line 586, in readinto
    return self._sock.recv_into(b)
ConnectionResetError: [Errno 104] Connection reset by peer
----------------------------------------
/root/Anki/reader/views.py:79: UnorderedObjectListWarning: Pagination may yield inconsistent results with an unordered object_list: <class 'reader.models.Book'> QuerySet.
  paginator = Paginator(books, 10)  # 20 articles in each page
Traceback (most recent call last):
  File "/usr/lib/python3.6/wsgiref/handlers.py", line 138, in run
    self.finish_response()
  File "/usr/lib/python3.6/wsgiref/handlers.py", line 180, in finish_response
    self.write(data)
  File "/usr/lib/python3.6/wsgiref/handlers.py", line 274, in write
    self.send_headers()
  File "/usr/lib/python3.6/wsgiref/handlers.py", line 332, in send_headers
    self.send_preamble()
  File "/usr/lib/python3.6/wsgiref/handlers.py", line 252, in send_preamble
    self._write(('HTTP/%s %s\r\n' % (self.http_version,self.status)).encode('iso-8859-1'))
  File "/usr/lib/python3.6/wsgiref/handlers.py", line 453, in _write
    result = self.stdout.write(data)
  File "/usr/lib/python3.6/socketserver.py", line 803, in write
    self._sock.sendall(b)
ConnectionResetError: [Errno 104] Connection reset by peer
----------------------------------------
Exception happened during processing of request from ('209.159.147.166', 38836)
Traceback (most recent call last):
  File "/usr/lib/python3.6/wsgiref/handlers.py", line 138, in run
    self.finish_response()
  File "/usr/lib/python3.6/wsgiref/handlers.py", line 180, in finish_response
    self.write(data)
  File "/usr/lib/python3.6/wsgiref/handlers.py", line 274, in write
    self.send_headers()
  File "/usr/lib/python3.6/wsgiref/handlers.py", line 332, in send_headers
    self.send_preamble()
  File "/usr/lib/python3.6/wsgiref/handlers.py", line 252, in send_preamble
    self._write(('HTTP/%s %s\r\n' % (self.http_version,self.status)).encode('iso-8859-1'))
  File "/usr/lib/python3.6/wsgiref/handlers.py", line 453, in _write
    result = self.stdout.write(data)
  File "/usr/lib/python3.6/socketserver.py", line 803, in write
    self._sock.sendall(b)
ConnectionResetError: [Errno 104] Connection reset by peer

During handling of the above exception, another exception occurred:

Traceback (most recent call last):
  File "/usr/lib/python3.6/wsgiref/handlers.py", line 141, in run
    self.handle_error()
  File "/usr/local/lib/python3.6/dist-packages/django/core/servers/basehttp.py", line 119, in handle_error
    super().handle_error()
  File "/usr/lib/python3.6/wsgiref/handlers.py", line 368, in handle_error
    self.finish_response()
  File "/usr/lib/python3.6/wsgiref/handlers.py", line 180, in finish_response
    self.write(data)
  File "/usr/lib/python3.6/wsgiref/handlers.py", line 274, in write
    self.send_headers()
  File "/usr/lib/python3.6/wsgiref/handlers.py", line 331, in send_headers
    if not self.origin_server or self.client_is_modern():
  File "/usr/lib/python3.6/wsgiref/handlers.py", line 344, in client_is_modern
    return self.environ['SERVER_PROTOCOL'].upper() != 'HTTP/0.9'
TypeError: 'NoneType' object is not subscriptable

During handling of the above exception, another exception occurred:

Traceback (most recent call last):
  File "/usr/lib/python3.6/socketserver.py", line 654, in process_request_thread
    self.finish_request(request, client_address)
  File "/usr/lib/python3.6/socketserver.py", line 364, in finish_request
    self.RequestHandlerClass(request, client_address, self)
  File "/usr/lib/python3.6/socketserver.py", line 724, in __init__
    self.handle()
  File "/usr/local/lib/python3.6/dist-packages/django/core/servers/basehttp.py", line 172, in handle
    self.handle_one_request()
  File "/usr/local/lib/python3.6/dist-packages/django/core/servers/basehttp.py", line 197, in handle_one_request
    handler.run(self.server.get_app())
  File "/usr/lib/python3.6/wsgiref/handlers.py", line 144, in run
    self.close()
  File "/usr/local/lib/python3.6/dist-packages/django/core/servers/basehttp.py", line 114, in close
    super().close()
  File "/usr/lib/python3.6/wsgiref/simple_server.py", line 35, in close
    self.status.split(' ',1)[0], self.bytes_sent
AttributeError: 'NoneType' object has no attribute 'split'
----------------------------------------
----------------------------------------
Exception happened during processing of request from ('106.12.3.163', 49296)
Traceback (most recent call last):
  File "/usr/lib/python3.6/socketserver.py", line 654, in process_request_thread
    self.finish_request(request, client_address)
  File "/usr/lib/python3.6/socketserver.py", line 364, in finish_request
    self.RequestHandlerClass(request, client_address, self)
  File "/usr/lib/python3.6/socketserver.py", line 724, in __init__
    self.handle()
  File "/usr/local/lib/python3.6/dist-packages/django/core/servers/basehttp.py", line 174, in handle
    self.handle_one_request()
  File "/usr/local/lib/python3.6/dist-packages/django/core/servers/basehttp.py", line 182, in handle_one_request
    self.raw_requestline = self.rfile.readline(65537)
  File "/usr/lib/python3.6/socket.py", line 586, in readinto
    return self._sock.recv_into(b)
ConnectionResetError: [Errno 104] Connection reset by peer
----------------------------------------
----------------------------------------
Exception happened during processing of request from ('184.105.247.196', 57436)
Traceback (most recent call last):
  File "/usr/lib/python3.6/socketserver.py", line 654, in process_request_thread
    self.finish_request(request, client_address)
  File "/usr/lib/python3.6/socketserver.py", line 364, in finish_request
    self.RequestHandlerClass(request, client_address, self)
  File "/usr/lib/python3.6/socketserver.py", line 724, in __init__
    self.handle()
  File "/usr/local/lib/python3.6/dist-packages/django/core/servers/basehttp.py", line 174, in handle
    self.handle_one_request()
  File "/usr/local/lib/python3.6/dist-packages/django/core/servers/basehttp.py", line 182, in handle_one_request
    self.raw_requestline = self.rfile.readline(65537)
  File "/usr/lib/python3.6/socket.py", line 586, in readinto
    return self._sock.recv_into(b)
ConnectionResetError: [Errno 104] Connection reset by peer
----------------------------------------
Traceback (most recent call last):
  File "/usr/lib/python3.6/wsgiref/handlers.py", line 138, in run
    self.finish_response()
  File "/usr/lib/python3.6/wsgiref/handlers.py", line 180, in finish_response
    self.write(data)
  File "/usr/lib/python3.6/wsgiref/handlers.py", line 274, in write
    self.send_headers()
  File "/usr/lib/python3.6/wsgiref/handlers.py", line 332, in send_headers
    self.send_preamble()
  File "/usr/lib/python3.6/wsgiref/handlers.py", line 252, in send_preamble
    self._write(('HTTP/%s %s\r\n' % (self.http_version,self.status)).encode('iso-8859-1'))
  File "/usr/lib/python3.6/wsgiref/handlers.py", line 453, in _write
    result = self.stdout.write(data)
  File "/usr/lib/python3.6/socketserver.py", line 803, in write
    self._sock.sendall(b)
ConnectionResetError: [Errno 104] Connection reset by peer
----------------------------------------
Exception happened during processing of request from ('92.118.234.202', 56250)
Traceback (most recent call last):
  File "/usr/lib/python3.6/wsgiref/handlers.py", line 138, in run
    self.finish_response()
  File "/usr/lib/python3.6/wsgiref/handlers.py", line 180, in finish_response
    self.write(data)
  File "/usr/lib/python3.6/wsgiref/handlers.py", line 274, in write
    self.send_headers()
  File "/usr/lib/python3.6/wsgiref/handlers.py", line 332, in send_headers
    self.send_preamble()
  File "/usr/lib/python3.6/wsgiref/handlers.py", line 252, in send_preamble
    self._write(('HTTP/%s %s\r\n' % (self.http_version,self.status)).encode('iso-8859-1'))
  File "/usr/lib/python3.6/wsgiref/handlers.py", line 453, in _write
    result = self.stdout.write(data)
  File "/usr/lib/python3.6/socketserver.py", line 803, in write
    self._sock.sendall(b)
ConnectionResetError: [Errno 104] Connection reset by peer

During handling of the above exception, another exception occurred:

Traceback (most recent call last):
  File "/usr/lib/python3.6/wsgiref/handlers.py", line 141, in run
    self.handle_error()
  File "/usr/local/lib/python3.6/dist-packages/django/core/servers/basehttp.py", line 119, in handle_error
    super().handle_error()
  File "/usr/lib/python3.6/wsgiref/handlers.py", line 368, in handle_error
    self.finish_response()
  File "/usr/lib/python3.6/wsgiref/handlers.py", line 180, in finish_response
    self.write(data)
  File "/usr/lib/python3.6/wsgiref/handlers.py", line 274, in write
    self.send_headers()
  File "/usr/lib/python3.6/wsgiref/handlers.py", line 331, in send_headers
    if not self.origin_server or self.client_is_modern():
  File "/usr/lib/python3.6/wsgiref/handlers.py", line 344, in client_is_modern
    return self.environ['SERVER_PROTOCOL'].upper() != 'HTTP/0.9'
TypeError: 'NoneType' object is not subscriptable

During handling of the above exception, another exception occurred:

Traceback (most recent call last):
  File "/usr/lib/python3.6/socketserver.py", line 654, in process_request_thread
    self.finish_request(request, client_address)
  File "/usr/lib/python3.6/socketserver.py", line 364, in finish_request
    self.RequestHandlerClass(request, client_address, self)
  File "/usr/lib/python3.6/socketserver.py", line 724, in __init__
    self.handle()
  File "/usr/local/lib/python3.6/dist-packages/django/core/servers/basehttp.py", line 172, in handle
    self.handle_one_request()
  File "/usr/local/lib/python3.6/dist-packages/django/core/servers/basehttp.py", line 197, in handle_one_request
    handler.run(self.server.get_app())
  File "/usr/lib/python3.6/wsgiref/handlers.py", line 144, in run
    self.close()
  File "/usr/local/lib/python3.6/dist-packages/django/core/servers/basehttp.py", line 114, in close
    super().close()
  File "/usr/lib/python3.6/wsgiref/simple_server.py", line 35, in close
    self.status.split(' ',1)[0], self.bytes_sent
AttributeError: 'NoneType' object has no attribute 'split'
----------------------------------------
----------------------------------------
Exception happened during processing of request from ('2.56.59.20', 47416)
Traceback (most recent call last):
  File "/usr/lib/python3.6/socketserver.py", line 654, in process_request_thread
    self.finish_request(request, client_address)
  File "/usr/lib/python3.6/socketserver.py", line 364, in finish_request
    self.RequestHandlerClass(request, client_address, self)
  File "/usr/lib/python3.6/socketserver.py", line 724, in __init__
    self.handle()
  File "/usr/local/lib/python3.6/dist-packages/django/core/servers/basehttp.py", line 174, in handle
    self.handle_one_request()
  File "/usr/local/lib/python3.6/dist-packages/django/core/servers/basehttp.py", line 182, in handle_one_request
    self.raw_requestline = self.rfile.readline(65537)
  File "/usr/lib/python3.6/socket.py", line 586, in readinto
    return self._sock.recv_into(b)
ConnectionResetError: [Errno 104] Connection reset by peer
----------------------------------------
----------------------------------------
Exception happened during processing of request from ('106.12.3.163', 38824)
Traceback (most recent call last):
  File "/usr/lib/python3.6/socketserver.py", line 654, in process_request_thread
    self.finish_request(request, client_address)
  File "/usr/lib/python3.6/socketserver.py", line 364, in finish_request
    self.RequestHandlerClass(request, client_address, self)
  File "/usr/lib/python3.6/socketserver.py", line 724, in __init__
    self.handle()
  File "/usr/local/lib/python3.6/dist-packages/django/core/servers/basehttp.py", line 174, in handle
    self.handle_one_request()
  File "/usr/local/lib/python3.6/dist-packages/django/core/servers/basehttp.py", line 182, in handle_one_request
    self.raw_requestline = self.rfile.readline(65537)
  File "/usr/lib/python3.6/socket.py", line 586, in readinto
    return self._sock.recv_into(b)
ConnectionResetError: [Errno 104] Connection reset by peer
----------------------------------------
----------------------------------------
Exception happened during processing of request from ('106.12.3.163', 57472)
Traceback (most recent call last):
  File "/usr/lib/python3.6/socketserver.py", line 654, in process_request_thread
    self.finish_request(request, client_address)
  File "/usr/lib/python3.6/socketserver.py", line 364, in finish_request
    self.RequestHandlerClass(request, client_address, self)
  File "/usr/lib/python3.6/socketserver.py", line 724, in __init__
    self.handle()
  File "/usr/local/lib/python3.6/dist-packages/django/core/servers/basehttp.py", line 174, in handle
    self.handle_one_request()
  File "/usr/local/lib/python3.6/dist-packages/django/core/servers/basehttp.py", line 182, in handle_one_request
    self.raw_requestline = self.rfile.readline(65537)
  File "/usr/lib/python3.6/socket.py", line 586, in readinto
    return self._sock.recv_into(b)
ConnectionResetError: [Errno 104] Connection reset by peer
----------------------------------------
Traceback (most recent call last):
  File "/usr/lib/python3.6/wsgiref/handlers.py", line 138, in run
    self.finish_response()
  File "/usr/lib/python3.6/wsgiref/handlers.py", line 180, in finish_response
    self.write(data)
  File "/usr/lib/python3.6/wsgiref/handlers.py", line 274, in write
    self.send_headers()
  File "/usr/lib/python3.6/wsgiref/handlers.py", line 332, in send_headers
    self.send_preamble()
  File "/usr/lib/python3.6/wsgiref/handlers.py", line 252, in send_preamble
    self._write(('HTTP/%s %s\r\n' % (self.http_version,self.status)).encode('iso-8859-1'))
  File "/usr/lib/python3.6/wsgiref/handlers.py", line 453, in _write
    result = self.stdout.write(data)
  File "/usr/lib/python3.6/socketserver.py", line 803, in write
    self._sock.sendall(b)
ConnectionResetError: [Errno 104] Connection reset by peer
----------------------------------------
Exception happened during processing of request from ('92.118.234.202', 51164)
Traceback (most recent call last):
  File "/usr/lib/python3.6/wsgiref/handlers.py", line 138, in run
    self.finish_response()
  File "/usr/lib/python3.6/wsgiref/handlers.py", line 180, in finish_response
    self.write(data)
  File "/usr/lib/python3.6/wsgiref/handlers.py", line 274, in write
    self.send_headers()
  File "/usr/lib/python3.6/wsgiref/handlers.py", line 332, in send_headers
    self.send_preamble()
  File "/usr/lib/python3.6/wsgiref/handlers.py", line 252, in send_preamble
    self._write(('HTTP/%s %s\r\n' % (self.http_version,self.status)).encode('iso-8859-1'))
  File "/usr/lib/python3.6/wsgiref/handlers.py", line 453, in _write
    result = self.stdout.write(data)
  File "/usr/lib/python3.6/socketserver.py", line 803, in write
    self._sock.sendall(b)
ConnectionResetError: [Errno 104] Connection reset by peer

During handling of the above exception, another exception occurred:

Traceback (most recent call last):
  File "/usr/lib/python3.6/wsgiref/handlers.py", line 141, in run
    self.handle_error()
  File "/usr/local/lib/python3.6/dist-packages/django/core/servers/basehttp.py", line 119, in handle_error
    super().handle_error()
  File "/usr/lib/python3.6/wsgiref/handlers.py", line 368, in handle_error
    self.finish_response()
  File "/usr/lib/python3.6/wsgiref/handlers.py", line 180, in finish_response
    self.write(data)
  File "/usr/lib/python3.6/wsgiref/handlers.py", line 274, in write
    self.send_headers()
  File "/usr/lib/python3.6/wsgiref/handlers.py", line 331, in send_headers
    if not self.origin_server or self.client_is_modern():
  File "/usr/lib/python3.6/wsgiref/handlers.py", line 344, in client_is_modern
    return self.environ['SERVER_PROTOCOL'].upper() != 'HTTP/0.9'
TypeError: 'NoneType' object is not subscriptable

During handling of the above exception, another exception occurred:

Traceback (most recent call last):
  File "/usr/lib/python3.6/socketserver.py", line 654, in process_request_thread
    self.finish_request(request, client_address)
  File "/usr/lib/python3.6/socketserver.py", line 364, in finish_request
    self.RequestHandlerClass(request, client_address, self)
  File "/usr/lib/python3.6/socketserver.py", line 724, in __init__
    self.handle()
  File "/usr/local/lib/python3.6/dist-packages/django/core/servers/basehttp.py", line 172, in handle
    self.handle_one_request()
  File "/usr/local/lib/python3.6/dist-packages/django/core/servers/basehttp.py", line 197, in handle_one_request
    handler.run(self.server.get_app())
  File "/usr/lib/python3.6/wsgiref/handlers.py", line 144, in run
    self.close()
  File "/usr/local/lib/python3.6/dist-packages/django/core/servers/basehttp.py", line 114, in close
    super().close()
  File "/usr/lib/python3.6/wsgiref/simple_server.py", line 35, in close
    self.status.split(' ',1)[0], self.bytes_sent
AttributeError: 'NoneType' object has no attribute 'split'
----------------------------------------
----------------------------------------
Exception happened during processing of request from ('106.12.3.163', 60274)
Traceback (most recent call last):
  File "/usr/lib/python3.6/socketserver.py", line 654, in process_request_thread
    self.finish_request(request, client_address)
  File "/usr/lib/python3.6/socketserver.py", line 364, in finish_request
    self.RequestHandlerClass(request, client_address, self)
  File "/usr/lib/python3.6/socketserver.py", line 724, in __init__
    self.handle()
  File "/usr/local/lib/python3.6/dist-packages/django/core/servers/basehttp.py", line 174, in handle
    self.handle_one_request()
  File "/usr/local/lib/python3.6/dist-packages/django/core/servers/basehttp.py", line 182, in handle_one_request
    self.raw_requestline = self.rfile.readline(65537)
  File "/usr/lib/python3.6/socket.py", line 586, in readinto
    return self._sock.recv_into(b)
ConnectionResetError: [Errno 104] Connection reset by peer
----------------------------------------
Traceback (most recent call last):
  File "/usr/lib/python3.6/wsgiref/handlers.py", line 138, in run
    self.finish_response()
  File "/usr/lib/python3.6/wsgiref/handlers.py", line 180, in finish_response
    self.write(data)
  File "/usr/lib/python3.6/wsgiref/handlers.py", line 274, in write
    self.send_headers()
  File "/usr/lib/python3.6/wsgiref/handlers.py", line 332, in send_headers
    self.send_preamble()
  File "/usr/lib/python3.6/wsgiref/handlers.py", line 252, in send_preamble
    self._write(('HTTP/%s %s\r\n' % (self.http_version,self.status)).encode('iso-8859-1'))
  File "/usr/lib/python3.6/wsgiref/handlers.py", line 453, in _write
    result = self.stdout.write(data)
  File "/usr/lib/python3.6/socketserver.py", line 803, in write
    self._sock.sendall(b)
ConnectionResetError: [Errno 104] Connection reset by peer
----------------------------------------
Exception happened during processing of request from ('219.231.139.152', 52575)
Traceback (most recent call last):
  File "/usr/lib/python3.6/socketserver.py", line 654, in process_request_thread
    self.finish_request(request, client_address)
  File "/usr/lib/python3.6/socketserver.py", line 364, in finish_request
    self.RequestHandlerClass(request, client_address, self)
  File "/usr/lib/python3.6/socketserver.py", line 724, in __init__
    self.handle()
  File "/usr/local/lib/python3.6/dist-packages/django/core/servers/basehttp.py", line 174, in handle
    self.handle_one_request()
  File "/usr/local/lib/python3.6/dist-packages/django/core/servers/basehttp.py", line 182, in handle_one_request
    self.raw_requestline = self.rfile.readline(65537)
  File "/usr/lib/python3.6/socket.py", line 586, in readinto
    return self._sock.recv_into(b)
ConnectionResetError: [Errno 104] Connection reset by peer
----------------------------------------
----------------------------------------
Exception happened during processing of request from ('109.237.103.118', 39950)
Traceback (most recent call last):
  File "/usr/lib/python3.6/socketserver.py", line 654, in process_request_thread
    self.finish_request(request, client_address)
  File "/usr/lib/python3.6/socketserver.py", line 364, in finish_request
    self.RequestHandlerClass(request, client_address, self)
  File "/usr/lib/python3.6/socketserver.py", line 724, in __init__
    self.handle()
  File "/usr/local/lib/python3.6/dist-packages/django/core/servers/basehttp.py", line 174, in handle
    self.handle_one_request()
  File "/usr/local/lib/python3.6/dist-packages/django/core/servers/basehttp.py", line 182, in handle_one_request
    self.raw_requestline = self.rfile.readline(65537)
  File "/usr/lib/python3.6/socket.py", line 586, in readinto
    return self._sock.recv_into(b)
ConnectionResetError: [Errno 104] Connection reset by peer
----------------------------------------
----------------------------------------
Exception happened during processing of request from ('210.75.240.10', 54146)
Traceback (most recent call last):
  File "/usr/lib/python3.6/socketserver.py", line 654, in process_request_thread
    self.finish_request(request, client_address)
  File "/usr/lib/python3.6/socketserver.py", line 364, in finish_request
    self.RequestHandlerClass(request, client_address, self)
  File "/usr/lib/python3.6/socketserver.py", line 724, in __init__
    self.handle()
  File "/usr/local/lib/python3.6/dist-packages/django/core/servers/basehttp.py", line 174, in handle
    self.handle_one_request()
  File "/usr/local/lib/python3.6/dist-packages/django/core/servers/basehttp.py", line 182, in handle_one_request
    self.raw_requestline = self.rfile.readline(65537)
  File "/usr/lib/python3.6/socket.py", line 586, in readinto
    return self._sock.recv_into(b)
ConnectionResetError: [Errno 104] Connection reset by peer
----------------------------------------
----------------------------------------
Exception happened during processing of request from ('210.75.240.10', 53253)
Traceback (most recent call last):
  File "/usr/lib/python3.6/socketserver.py", line 654, in process_request_thread
    self.finish_request(request, client_address)
  File "/usr/lib/python3.6/socketserver.py", line 364, in finish_request
    self.RequestHandlerClass(request, client_address, self)
  File "/usr/lib/python3.6/socketserver.py", line 724, in __init__
    self.handle()
  File "/usr/local/lib/python3.6/dist-packages/django/core/servers/basehttp.py", line 174, in handle
    self.handle_one_request()
  File "/usr/local/lib/python3.6/dist-packages/django/core/servers/basehttp.py", line 182, in handle_one_request
    self.raw_requestline = self.rfile.readline(65537)
  File "/usr/lib/python3.6/socket.py", line 586, in readinto
    return self._sock.recv_into(b)
ConnectionResetError: [Errno 104] Connection reset by peer
----------------------------------------
----------------------------------------
Exception happened during processing of request from ('210.75.240.10', 55407)
Traceback (most recent call last):
  File "/usr/lib/python3.6/socketserver.py", line 654, in process_request_thread
    self.finish_request(request, client_address)
  File "/usr/lib/python3.6/socketserver.py", line 364, in finish_request
    self.RequestHandlerClass(request, client_address, self)
  File "/usr/lib/python3.6/socketserver.py", line 724, in __init__
    self.handle()
  File "/usr/local/lib/python3.6/dist-packages/django/core/servers/basehttp.py", line 174, in handle
    self.handle_one_request()
  File "/usr/local/lib/python3.6/dist-packages/django/core/servers/basehttp.py", line 182, in handle_one_request
    self.raw_requestline = self.rfile.readline(65537)
  File "/usr/lib/python3.6/socket.py", line 586, in readinto
    return self._sock.recv_into(b)
ConnectionResetError: [Errno 104] Connection reset by peer
----------------------------------------
----------------------------------------
Exception happened during processing of request from ('210.75.240.10', 56245)
Traceback (most recent call last):
  File "/usr/lib/python3.6/socketserver.py", line 654, in process_request_thread
    self.finish_request(request, client_address)
  File "/usr/lib/python3.6/socketserver.py", line 364, in finish_request
    self.RequestHandlerClass(request, client_address, self)
  File "/usr/lib/python3.6/socketserver.py", line 724, in __init__
    self.handle()
  File "/usr/local/lib/python3.6/dist-packages/django/core/servers/basehttp.py", line 174, in handle
    self.handle_one_request()
  File "/usr/local/lib/python3.6/dist-packages/django/core/servers/basehttp.py", line 182, in handle_one_request
    self.raw_requestline = self.rfile.readline(65537)
  File "/usr/lib/python3.6/socket.py", line 586, in readinto
    return self._sock.recv_into(b)
ConnectionResetError: [Errno 104] Connection reset by peer
----------------------------------------
----------------------------------------
Exception happened during processing of request from ('157.90.182.30', 28066)
Traceback (most recent call last):
  File "/usr/lib/python3.6/socketserver.py", line 654, in process_request_thread
    self.finish_request(request, client_address)
  File "/usr/lib/python3.6/socketserver.py", line 364, in finish_request
    self.RequestHandlerClass(request, client_address, self)
  File "/usr/lib/python3.6/socketserver.py", line 724, in __init__
    self.handle()
  File "/usr/local/lib/python3.6/dist-packages/django/core/servers/basehttp.py", line 174, in handle
    self.handle_one_request()
  File "/usr/local/lib/python3.6/dist-packages/django/core/servers/basehttp.py", line 182, in handle_one_request
    self.raw_requestline = self.rfile.readline(65537)
  File "/usr/lib/python3.6/socket.py", line 586, in readinto
    return self._sock.recv_into(b)
ConnectionResetError: [Errno 104] Connection reset by peer
----------------------------------------
----------------------------------------
Exception happened during processing of request from ('167.94.138.118', 45056)
Traceback (most recent call last):
  File "/usr/lib/python3.6/socketserver.py", line 654, in process_request_thread
    self.finish_request(request, client_address)
  File "/usr/lib/python3.6/socketserver.py", line 364, in finish_request
    self.RequestHandlerClass(request, client_address, self)
  File "/usr/lib/python3.6/socketserver.py", line 724, in __init__
    self.handle()
  File "/usr/local/lib/python3.6/dist-packages/django/core/servers/basehttp.py", line 172, in handle
    self.handle_one_request()
  File "/usr/local/lib/python3.6/dist-packages/django/core/servers/basehttp.py", line 182, in handle_one_request
    self.raw_requestline = self.rfile.readline(65537)
  File "/usr/lib/python3.6/socket.py", line 586, in readinto
    return self._sock.recv_into(b)
ConnectionResetError: [Errno 104] Connection reset by peer
----------------------------------------
----------------------------------------
Exception happened during processing of request from ('167.94.138.118', 45422)
Traceback (most recent call last):
  File "/usr/lib/python3.6/socketserver.py", line 654, in process_request_thread
    self.finish_request(request, client_address)
